Workbook

Sheet Overview
C2: YOUR LOGO HERE
C4: Financial Model
G5: Welcome! This template was created by Forecastr's team of Financial Analysts and Fractional CFOs to help our fellow founders create better financial models for their startups and small businesses. Forecastr is an out-of-the-box finance function for your business. We provide the tools and support you need to create an investor-grade financial model. Our analysts work with you every step of the way to build a model that's customized to fit your business, keep it up to date, and generate insightful reports to share with your investors and other stakeholders. ✔ Impress your investors ✔ Hit your growth targets ✔ Never run out of cash
C7: Your Website Link Here
C10: Table of Contents
C12: Assumptions
C14: Financials
I18: SCHEDULE A MODELING SESSION WITH A MEMBER OF OUR TEAM

Sheet Assumptions
B1: Year Counter | G1: 1 | H1: 1 | I1: 1 | J1: 1 | K1: 1 | L1: 1 | M1: 1 | N1: 1 | O1: 1 | P1: 1 | Q1: 1 | R1: 1 | S1: =G1+1 -> 2 | T1: =H1+1 -> 2 | U1: =I1+1 -> 2 | V1: =J1+1 -> 2 | W1: =K1+1 -> 2 | X1: =L1+1 -> 2 | Y1: =M1+1 -> 2 | Z1: =N1+1 -> 2 | ... BN1: =BB1+1 -> 5
B2: Year | G2: =YEAR(G4) -> 2026 | H2: =YEAR(H4) -> 2026 | I2: =YEAR(I4) -> 2026 | J2: =YEAR(J4) -> 2026 | K2: =YEAR(K4) -> 2026 | L2: =YEAR(L4) -> 2026 | M2: =YEAR(M4) -> 2026 | N2: =YEAR(N4) -> 2026 | ... BN2: =YEAR(BN4) -> 2031
B3: Month Counter | G3: 1 | H3: =G3+1 -> 2 | I3: =H3+1 -> 3 | J3: =I3+1 -> 4 | K3: =J3+1 -> 5 | L3: =K3+1 -> 6 | M3: =L3+1 -> 7 | N3: =M3+1 -> 8 | O3: =N3+1 -> 9 | ... BN3: =BM3+1 -> 60
B4: Date | G4: =eomonth(today(),0) -> 46081 | H4: =EOMONTH(G4,1) -> 46112 | I4: =EOMONTH(H4,1) -> 46142 | J4: =EOMONTH(I4,1) -> 46173 | K4: =EOMONTH(J4,1) -> 46203 | L4: =EOMONTH(K4,1) -> 46234 | M4: =EOMONTH(L4,1) -> 46265 | N4: =EOMONTH(M4,1) -> 46295 | O4: =EOMONTH(N4,1) -> 46326 | ... BN4: =EOMONTH(BM4,1) -> 47879
B6: Customer Acquisition:
B8: Build Customer Acquisition Channels
B10: Organic / Word of Mouth
B11: Leads | D11: 1000 | G11: =D11 -> 1000 | H11: =G11 -> 1000 | I11: =G11 -> 1000 | J11: =I11 -> 1000 | K11: =J11 -> 1000 | L11: =K11 -> 1000 | M11: =L11 -> 1000 | N11: =M11 -> 1000 | O11: =N11 -> 1000 | P11: =O11 -> 1000 | Q11: =P11 -> 1000 | ... BN11: =BM11 -> 1000
B12: Conversion Rate | D12: 0.1 | G12: =D12 -> 0.1 | H12: =G12 -> 0.1 | I12: =G12 -> 0.1 | J12: =I12 -> 0.1 | K12: =J12 -> 0.1 | L12: =K12 -> 0.1 | M12: =L12 -> 0.1 | N12: =M12 -> 0.1 | O12: =N12 -> 0.1 | P12: =O12 -> 0.1 | Q12: =P12 -> 0.1 | ... BN12: =BM12 -> 0.1
B13: New Customers | G13: =G11*G12 -> 100 | H13: =H11*H12 -> 100 | I13: =I11*I12 -> 100 | J13: =J11*J12 -> 100 | K13: =K11*K12 -> 100 | L13: =L11*L12 -> 100 | M13: =M11*M12 -> 100 | N13: =N11*N12 -> 100 | ... BN13: =BN11*BN12 -> 100
B15: Paid Advertising
B16: Budget per Month | D16: 2500 | G16: =D16 -> 2500 | H16: =G16+(0.1*G16) -> 2750 | I16: =H16+(0.1*H16) -> 3025 | J16: =I16+(0.1*I16) -> 3327.5 | K16: =J16+(0.1*J16) -> 3660.25 | L16: =K16+(0.1*K16) -> 4026.275 | M16: =L16 -> 4026.275 | N16: =M16 -> 4026.275 | O16: =N16 -> 4026.275 | P16: =O16 -> 4026.275 | Q16: =P16 -> 4026.275 | R16: =Q16 -> 4026.275 | S16: =R16 -> 4026.275 | T16: =S16 -> 4026.275 | ... BN16: =BM16 -> 4026.275
B17: Average CPC | D17: 2 | G17: =D17 -> 2 | H17: =G17 -> 2 | I17: =H17 -> 2 | J17: =I17 -> 2 | K17: =J17 -> 2 | L17: =K17 -> 2 | M17: =L17 -> 2 | N17: =M17 -> 2 | O17: =N17 -> 2 | ... BN17: =BM17 -> 2
B18: Conversion Rate | D18: 0.15 | G18: =D18 -> 0.15 | H18: =G18 -> 0.15 | I18: =H18 -> 0.15 | J18: =I18 -> 0.15 | K18: =J18 -> 0.15 | L18: =K18 -> 0.15 | M18: =L18 -> 0.15 | N18: =M18 -> 0.15 | O18: =N18 -> 0.15 | ... BN18: =BM18 -> 0.15
B19: New Customers | G19: =iferror((G16/G17)*G18,0) -> 187.5 | H19: =iferror((H16/H17)*H18,0) -> 206.25 | I19: =iferror((I16/I17)*I18,0) -> 226.875 | J19: =iferror((J16/J17)*J18,0) -> 249.5625 | K19: =iferror((K16/K17)*K18,0) -> 274.51875 | L19: =iferror((L16/L17)*L18,0) -> 301.97062 | M19: =iferror((M16/M17)*M18,0) -> 301.97062 | N19: =iferror((N16/N17)*N18,0) -> 301.97062 | ... BN19: =iferror((BN16/BN17)*BN18,0) -> 301.97062
B21: Affiliates
B22: Number of Affiliates | D22: 5 | G22: =D22 -> 5 | H22: =G22 -> 5 | I22: =H22 -> 5 | J22: =I22 -> 5 | K22: =J22 -> 5 | L22: =K22 -> 5 | M22: =L22 -> 5 | N22: =M22 -> 5 | O22: =N22 -> 5 | ... BN22: =BM22 -> 5
B23: New Monthly Leads per Affiliate | D23: 50 | G23: =D23 -> 50 | H23: =G23 -> 50 | I23: =H23 -> 50 | J23: =I23 -> 50 | K23: =J23 -> 50 | L23: =K23 -> 50 | M23: =L23 -> 50 | N23: =M23 -> 50 | O23: =N23 -> 50 | ... BN23: =BM23 -> 50
B24: Conversion Rate | D24: 0.05 | G24: =D24 -> 0.05 | H24: =G24 -> 0.05 | I24: =H24 -> 0.05 | J24: =I24 -> 0.05 | K24: =J24 -> 0.05 | L24: =K24 -> 0.05 | M24: =L24 -> 0.05 | N24: =M24 -> 0.05 | O24: =N24 -> 0.05 | ... BN24: =BM24 -> 0.05
B25: New Customers | G25: =G22*G23*G24 -> 12.5 | H25: =H22*H23*H24 -> 12.5 | I25: =I22*I23*I24 -> 12.5 | J25: =J22*J23*J24 -> 12.5 | K25: =K22*K23*K24 -> 12.5 | L25: =L22*L23*L24 -> 12.5 | M25: =M22*M23*M24 -> 12.5 | N25: =N22*N23*N24 -> 12.5 | ... BN25: =BN22*BN23*BN24 -> 12.5
B27: Conferences
B28: Conferences Atteneded | G28: 1 | K28: 1 | L28: 1 | Q28: 1 | R28: 1 | S28: 1 | T28: 1 | U28: 1 | V28: 1 | W28: 1 | X28: 1 | Y28: 1 | Z28: 1 | AA28: 1 | AB28: 1 | AC28: 1 | AD28: 1 | AE28: 1 | AF28: 1 | AG28: 1 | AH28: 1 | AI28: 1 | AJ28: 1 | AK28: 1 | AL28: 1 | AM28: 1 | AN28: 1 | AO28: 1 | AP28: 1 | AQ28: 1 | AR28: 1 | AS28: 1 | AT28: 1 | AU28: 1 | AV28: 1 | AW28: 1 | AX28: 1 | AY28: 1 | AZ28: 1 | BA28: 1 | BB28: 1 | BC28: 1 | BD28: 1 | BE28: 1 | BF28: 1 | BG28: 1 | BH28: 1 | BI28: 1 | BJ28: 1 | BK28: 1 | BL28: 1 | BM28: 1 | BN28: 1
B29: New Leads per Conference | D29: 50 | G29: =D29 -> 50 | H29: =G29 -> 50 | I29: =H29 -> 50 | J29: =I29 -> 50 | K29: =J29 -> 50 | L29: =K29 -> 50 | M29: =L29 -> 50 | N29: =M29 -> 50 | O29: =N29 -> 50 | ... BN29: =BM29 -> 50
B30: Conversion Rate | D30: 0.05 | G30: 0.02 | H30: =G30 -> 0.02 | I30: =H30 -> 0.02 | J30: =I30 -> 0.02 | K30: =J30 -> 0.02 | L30: =K30 -> 0.02 | M30: =L30 -> 0.02 | N30: =M30 -> 0.02 | O30: =N30 -> 0.02 | ... BN30: =BM30 -> 0.02
B31: New Customers | G31: =G28*G29*G30 -> 1 | H31: =H28*H29*H30 -> 0 | I31: =I28*I29*I30 -> 0 | J31: =J28*J29*J30 -> 0 | K31: =K28*K29*K30 -> 1 | L31: =L28*L29*L30 -> 1 | M31: =M28*M29*M30 -> 0 | N31: =N28*N29*N30 -> 0 | ... BN31: =BN28*BN29*BN30 -> 1
B33: Influencers
B34: Number of Influencers | D34: 2 | G34: =D34 -> 2 | H34: =G34 -> 2 | I34: =H34 -> 2 | J34: =I34 -> 2 | K34: =J34 -> 2 | L34: =K34 -> 2 | M34: =L34 -> 2 | N34: =M34 -> 2 | O34: =N34 -> 2 | ... BN34: =BM34 -> 2
B35: New Monthly Posts per Influencer | D35: 5 | G35: =D35 -> 5 | H35: =G35 -> 5 | I35: =H35 -> 5 | J35: =I35 -> 5 | K35: =J35 -> 5 | L35: =K35 -> 5 | M35: =L35 -> 5 | N35: =M35 -> 5 | O35: =N35 -> 5 | ... BN35: =BM35 -> 5
B36: New Monthly Leads per Post | D36: 100 | G36: =D36 -> 100 | H36: =G36 -> 100 | I36: =H36 -> 100 | J36: =I36 -> 100 | K36: =J36 -> 100 | L36: =K36 -> 100 | M36: =L36 -> 100 | N36: =M36 -> 100 | O36: =N36 -> 100 | ... BN36: =BM36 -> 100
B37: Conversion Rate | D37: 0.05 | G37: =D37 -> 0.05 | H37: =G37 -> 0.05 | I37: =H37 -> 0.05 | J37: =I37 -> 0.05 | K37: =J37 -> 0.05 | L37: =K37 -> 0.05 | M37: =L37 -> 0.05 | N37: =M37 -> 0.05 | O37: =N37 -> 0.05 | ... BN37: =BM37 -> 0.05
B38: New Customers | G38: =G34*G35*G36*G37 -> 50 | H38: =H34*H35*H36*H37 -> 50 | I38: =I34*I35*I36*I37 -> 50 | J38: =J34*J35*J36*J37 -> 50 | K38: =K34*K35*K36*K37 -> 50 | L38: =L34*L35*L36*L37 -> 50 | M38: =M34*M35*M36*M37 -> 50 | N38: =N34*N35*N36*N37 -> 50 | ... BN38: =BN34*BN35*BN36*BN37 -> 50
B40: Customer Referrals
B41: Previous Months New Customers | G41: =F71 | H41: =G71 -> 378.5 | I41: =H71 -> 406.9275 | J41: =I71 -> 427.97891 | K41: =J71 -> 450.98218 | L41: =K71 -> 477.28348 | M41: =L71 -> 505.12988 | N41: =M71 -> 504.54757 | ... BN41: =BM71 -> 505.55393
B42: Referral Percentage | D42: 0.3 | G42: =D42 -> 0.3 | H42: =G42 -> 0.3 | I42: =H42 -> 0.3 | J42: =I42 -> 0.3 | K42: =J42 -> 0.3 | L42: =K42 -> 0.3 | M42: =L42 -> 0.3 | N42: =M42 -> 0.3 | O42: =N42 -> 0.3 | ... BN42: =BM42 -> 0.3
B43: Conversion Rate | D43: 0.05 | G43: =D43 -> 0.05 | H43: =G43 -> 0.05 | I43: =H43 -> 0.05 | J43: =I43 -> 0.05 | K43: =J43 -> 0.05 | L43: =K43 -> 0.05 | M43: =L43 -> 0.05 | N43: =M43 -> 0.05 | O43: =N43 -> 0.05 | ... BN43: =BM43 -> 0.05
B44: New Customers | G44: =G41*G42*G43 -> 0 | H44: =H41*H42*H43 -> 5.6775 | I44: =I41*I42*I43 -> 6.1039125 | J44: =J41*J42*J43 -> 6.4196837 | K44: =K41*K42*K43 -> 6.7647328 | L44: =L41*L42*L43 -> 7.1592522 | M44: =M41*M42*M43 -> 7.5769482 | N44: =N41*N42*N43 -> 7.5682136 | ... BN44: =BN41*BN42*BN43 -> 7.583309
B46: Partnerships
B47: Active Partnerships | D47: 2 | G47: =D47 -> 2 | H47: =G47 -> 2 | I47: =H47 -> 2 | J47: =I47 -> 2 | K47: =J47 -> 2 | L47: =K47 -> 2 | M47: =L47 -> 2 | N47: =M47 -> 2 | O47: =N47 -> 2 | ... BN47: =BM47 -> 2
B48: New Monthly Leads per Partnership | D48: 100 | G48: =D48 -> 100 | H48: =G48 -> 100 | I48: =H48 -> 100 | J48: =I48 -> 100 | K48: =J48 -> 100 | L48: =K48 -> 100 | M48: =L48 -> 100 | N48: =M48 -> 100 | O48: =N48 -> 100 | ... BN48: =BM48 -> 100
B49: Conversion Rate | D49: 0.05 | G49: =D49 -> 0.05 | H49: =G49 -> 0.05 | I49: =H49 -> 0.05 | J49: =I49 -> 0.05 | K49: =J49 -> 0.05 | L49: =K49 -> 0.05 | M49: =L49 -> 0.05 | N49: =M49 -> 0.05 | O49: =N49 -> 0.05 | ... BN49: =BM49 -> 0.05
...

Sheet Financials
B1: Year Counter | F1: 1 | G1: 1 | H1: 1 | I1: 1 | J1: 1 | K1: 1 | L1: 1 | M1: 1 | N1: 1 | O1: 1 | P1: 1 | Q1: 1 | R1: =F1+1 -> 2 | S1: =G1+1 -> 2 | T1: =H1+1 -> 2 | U1: =I1+1 -> 2 | V1: =J1+1 -> 2 | W1: =K1+1 -> 2 | X1: =L1+1 -> 2 | Y1: =M1+1 -> 2 | ... BM1: =BA1+1 -> 5
B2: Year | F2: =YEAR(F4) -> 2026 | G2: =YEAR(G4) -> 2026 | H2: =YEAR(H4) -> 2026 | I2: =YEAR(I4) -> 2026 | J2: =YEAR(J4) -> 2026 | K2: =YEAR(K4) -> 2026 | L2: =YEAR(L4) -> 2026 | M2: =YEAR(M4) -> 2026 | ... BM2: =YEAR(BM4) -> 2031
B3: Month Counter | F3: 1 | G3: =F3+1 -> 2 | H3: =G3+1 -> 3 | I3: =H3+1 -> 4 | J3: =I3+1 -> 5 | K3: =J3+1 -> 6 | L3: =K3+1 -> 7 | M3: =L3+1 -> 8 | N3: =M3+1 -> 9 | ... BM3: =BL3+1 -> 60
B4: Date | F4: =Assumptions!G4 -> 46081 | G4: =EOMONTH(F4,1) -> 46112 | H4: =EOMONTH(G4,1) -> 46142 | I4: =EOMONTH(H4,1) -> 46173 | J4: =EOMONTH(I4,1) -> 46203 | K4: =EOMONTH(J4,1) -> 46234 | L4: =EOMONTH(K4,1) -> 46265 | M4: =EOMONTH(L4,1) -> 46295 | N4: =EOMONTH(M4,1) -> 46326 | ... BM4: =EOMONTH(BL4,1) -> 47879
B6: Income Statement:
B8: Revenue | F8: =SUM(F9:F11) -> 8516.25 | G8: =SUM(G9:G11) -> 17624.806 | H8: =SUM(H9:H11) -> 27157.336 | I8: =SUM(I9:I11) -> 37156.367 | J8: =SUM(J9:J11) -> 47694.506 | K8: =SUM(K9:K11) -> 58804.548 | L8: =SUM(L9:L11) -> 69844.73 | M8: =SUM(M9:M11) -> 80829.451 | ... BM8: =SUM(BM9:BM11) -> 602517.27
B9: =Assumptions!B75 -> Monthly SaaS Stream 1 | F9: =Assumptions!G84 -> 1892.5 | G9: =Assumptions!H84 -> 3879.825 | H9: =Assumptions!I84 -> 5922.7239 | I9: =Assumptions!J84 -> 8029.5668 | J9: =Assumptions!K84 -> 10215.245 | K9: =Assumptions!L84 -> 12485.513 | L9: =Assumptions!M84 -> 14696.113 | M9: =Assumptions!N84 -> 16851.405 | ... BM9: =Assumptions!BN84 -> 78520.951
B10: =Assumptions!B86 -> Monthly SaaS Stream 2 | F10: =Assumptions!G95 -> 2838.75 | G10: =Assumptions!H95 -> 5890.7063 | H10: =Assumptions!I95 -> 9100.5481 | I10: =Assumptions!J95 -> 12482.914 | J10: =Assumptions!K95 -> 16062.541 | K10: =Assumptions!L95 -> 19851.015 | L10: =Assumptions!M95 -> 23635.121 | M10: =Assumptions!N95 -> 27419.163 | ... BM10: =Assumptions!BN95 -> 224569.85
B11: =Assumptions!B97 -> Monthly SaaS Stream 3 | F11: =Assumptions!G106 -> 3785 | G11: =Assumptions!H106 -> 7854.275 | H11: =Assumptions!I106 -> 12134.064 | I11: =Assumptions!J106 -> 16643.886 | J11: =Assumptions!K106 -> 21416.721 | K11: =Assumptions!L106 -> 26468.02 | L11: =Assumptions!M106 -> 31513.495 | M11: =Assumptions!N106 -> 36558.884 | ... BM11: =Assumptions!BN106 -> 299426.47
B13: COGS | F13: =Assumptions!G150 -> 2980.6875 | G13: =Assumptions!H150 -> 6168.6822 | H13: =Assumptions!I150 -> 9505.0677 | I13: =Assumptions!J150 -> 13004.729 | J13: =Assumptions!K150 -> 16693.077 | K13: =Assumptions!L150 -> 20581.592 | L13: =Assumptions!M150 -> 24445.656 | M13: =Assumptions!N150 -> 28290.308 | ... BM13: =Assumptions!BN150 -> 210881.05
B15: Gross Profit | F15: =F8-F13 -> 5535.5625 | G15: =G8-G13 -> 11456.124 | H15: =H8-H13 -> 17652.268 | I15: =I8-I13 -> 24151.639 | J15: =J8-J13 -> 31001.429 | K15: =K8-K13 -> 38222.956 | L15: =L8-L13 -> 45399.075 | M15: =M8-M13 -> 52539.143 | ... BM15: =BM8-BM13 -> 391636.23
B16: Gross Margin | F16: =F15/F8 -> 0.65 | G16: =G15/G8 -> 0.65 | H16: =H15/H8 -> 0.65 | I16: =I15/I8 -> 0.65 | J16: =J15/J8 -> 0.65 | K16: =K15/K8 -> 0.65 | L16: =L15/L8 -> 0.65 | M16: =M15/M8 -> 0.65 | ... BM16: =BM15/BM8 -> 0.65
B18: Operating Expenses
B19: Salaries & Benefits | F19: =SUM(Assumptions!G113:G137) -> 218000 | G19: =SUM(Assumptions!H113:H137) -> 218000 | H19: =SUM(Assumptions!I113:I137) -> 218000 | I19: =SUM(Assumptions!J113:J137) -> 218000 | J19: =SUM(Assumptions!K113:K137) -> 218000 | K19: =SUM(Assumptions!L113:L137) -> 218000 | L19: =SUM(Assumptions!M113:M137) -> 218000 | M19: =SUM(Assumptions!N113:N137) -> 218000 | ... BM19: =SUM(Assumptions!BN113:BN137) -> 218000
B20: =Assumptions!B152 -> General & Admin | F20: 35000 | G20: =sum(Assumptions!H153:H163) -> 27500 | H20: =sum(Assumptions!I153:I163) -> 27500 | I20: =sum(Assumptions!J153:J163) -> 27500 | J20: =sum(Assumptions!K153:K163) -> 27500 | K20: =sum(Assumptions!L153:L163) -> 27500 | L20: =sum(Assumptions!M153:M163) -> 27500 | M20: =sum(Assumptions!N153:N163) -> 27500 | N20: =sum(Assumptions!O153:O163) -> 27500 | ... BM20: =sum(Assumptions!BN153:BN163) -> 27500
B21: =Assumptions!B166 -> Sales & Marketing | F21: =sum(Assumptions!G167:G168) -> 10681.3 | G21: =sum(Assumptions!H167:H168) -> 11409.985 | H21: =sum(Assumptions!I167:I168) -> 12172.587 | I21: =sum(Assumptions!J167:J168) -> 12972.509 | J21: =sum(Assumptions!K167:K168) -> 13815.561 | K21: =sum(Assumptions!L167:L168) -> 14704.364 | L21: =sum(Assumptions!M167:M168) -> 15587.578 | M21: =sum(Assumptions!N167:N168) -> 16466.356 | ... BM21: =sum(Assumptions!BN167:BN168) -> 58201.382
B22: =Assumptions!B171 -> Professional Fees | F22: 0 | G22: =SUM(Assumptions!H172:H174) -> 5000 | H22: =SUM(Assumptions!I172:I174) -> 5000 | I22: =SUM(Assumptions!J172:J174) -> 5000 | J22: =SUM(Assumptions!K172:K174) -> 5000 | K22: =SUM(Assumptions!L172:L174) -> 5000 | L22: =SUM(Assumptions!M172:M174) -> 5000 | M22: =SUM(Assumptions!N172:N174) -> 5000 | N22: =SUM(Assumptions!O172:O174) -> 5000 | ... BM22: =SUM(Assumptions!BN172:BN174) -> 5000
B23: =Assumptions!B177 -> Other | F23: =Assumptions!G178 -> 851.625 | G23: =Assumptions!H178 -> 1762.4806 | H23: =Assumptions!I178 -> 2715.7336 | I23: =Assumptions!J178 -> 3715.6367 | J23: =Assumptions!K178 -> 4769.4506 | K23: =Assumptions!L178 -> 5880.4547 | L23: =Assumptions!M178 -> 6984.473 | M23: =Assumptions!N178 -> 8082.9451 | ... BM23: =Assumptions!BN178 -> 60251.727
B24: Total Operating Expenses | F24: =SUM(F19:F23) -> 264532.92 | G24: =SUM(G19:G23) -> 263672.47 | H24: =SUM(H19:H23) -> 265388.32 | I24: =SUM(I19:I23) -> 267188.15 | J24: =SUM(J19:J23) -> 269085.01 | K24: =SUM(K19:K23) -> 271084.82 | L24: =SUM(L19:L23) -> 273072.05 | M24: =SUM(M19:M23) -> 275049.3 | ... BM24: =SUM(BM19:BM23) -> 368953.11
B26: EBITDA | F26: =F15-F24 -> -258997.36 | G26: =G15-G24 -> -252216.34 | H26: =H15-H24 -> -247736.05 | I26: =I15-I24 -> -243036.51 | J26: =J15-J24 -> -238083.58 | K26: =K15-K24 -> -232861.86 | L26: =L15-L24 -> -227672.98 | M26: =M15-M24 -> -222510.16 | ... BM26: =BM15-BM24 -> 22683.119
B27: Depreciation | F27: =SUM(Assumptions!G199:G202)-sum(Assumptions!E199:E202) -> 0 | G27: =SUM(Assumptions!H199:H202)-sum(Assumptions!G199:G202) -> 0 | H27: =SUM(Assumptions!I199:I202)-sum(Assumptions!H199:H202) -> 0 | I27: =SUM(Assumptions!J199:J202)-sum(Assumptions!I199:I202) -> 0 | J27: =SUM(Assumptions!K199:K202)-sum(Assumptions!J199:J202) -> 0 | K27: =SUM(Assumptions!L199:L202)-sum(Assumptions!K199:K202) -> 0 | L27: =SUM(Assumptions!M199:M202)-sum(Assumptions!L199:L202) -> 0 | M27: =SUM(Assumptions!N199:N202)-sum(Assumptions!M199:M202) -> 0 | N27: =SUM(Assumptions!O199:O202)-sum(Assumptions!N199:N202) -> 0 | ... BM27: =SUM(Assumptions!BN199:BN202)-sum(Assumptions!BM199:BM202) -> 0
B28: EBIT | F28: =F26-F27 -> -258997.36 | G28: =G26-G27 -> -252216.34 | H28: =H26-H27 -> -247736.05 | I28: =I26-I27 -> -243036.51 | J28: =J26-J27 -> -238083.58 | K28: =K26-K27 -> -232861.86 | L28: =L26-L27 -> -227672.98 | M28: =M26-M27 -> -222510.16 | ... BM28: =BM26-BM27 -> 22683.119
B29: Taxes | F29: =IF(F28>0,F28*Assumptions!$C$180,0) -> 0 | G29: =IF(G28>0,G28*Assumptions!$C$180,0) -> 0 | H29: =IF(H28>0,H28*Assumptions!$C$180,0) -> 0 | I29: =IF(I28>0,I28*Assumptions!$C$180,0) -> 0 | J29: =IF(J28>0,J28*Assumptions!$C$180,0) -> 0 | K29: =IF(K28>0,K28*Assumptions!$C$180,0) -> 0 | L29: =IF(L28>0,L28*Assumptions!$C$180,0) -> 0 | M29: =IF(M28>0,M28*Assumptions!$C$180,0) -> 0 | ... BM29: =IF(BM28>0,BM28*Assumptions!$C$180,0) -> 6124.4421
B30: Net Income | F30: =F28-F29 -> -258997.36 | G30: =G28-G29 -> -252216.34 | H30: =H28-H29 -> -247736.05 | I30: =I28-I29 -> -243036.51 | J30: =J28-J29 -> -238083.58 | K30: =K28-K29 -> -232861.86 | L30: =L28-L29 -> -227672.98 | M30: =M28-M29 -> -222510.16 | ... BM30: =BM28-BM29 -> 16558.677
B31: Net Margin | F31: =F30/F8 -> -30.412137 | G31: =G30/G8 -> -14.310304 | H31: =H30/H8 -> -9.1222516 | I31: =I30/I8 -> -6.5409114 | J31: =J30/J8 -> -4.991845 | K31: =K30/K8 -> -3.9599295 | L31: =L30/L8 -> -3.2597016 | M31: =M30/M8 -> -2.7528352 | ... BM31: =BM30/BM8 -> 0.027482493
B33: Balance Sheet:
B35: Assets
B36: Current Assets
B37: Cash | F37: =F80 -> 260251.32 | G37: =G80 -> 5894.467 | H37: =H80 -> -244081.73 | I37: =I80 -> -489468.01 | J37: =J80 -> -730028.05 | K37: =K80 -> -965500.78 | L37: =L80 -> -1195768.2 | M37: =M80 -> -1420859.8 | ... BM37: =BM80 -> -6474938.3
B38: Accounts Receivable | F38: =Assumptions!G190 -> 4258.125 | G38: =Assumptions!H190 -> 8812.4031 | H38: =Assumptions!I190 -> 13578.668 | I38: =Assumptions!J190 -> 18578.184 | J38: =Assumptions!K190 -> 23847.253 | K38: =Assumptions!L190 -> 29402.274 | L38: =Assumptions!M190 -> 34922.365 | M38: =Assumptions!N190 -> 40414.726 | ... BM38: =Assumptions!BN190 -> 301258.64
B39: Total Current Assets | F39: =SUM(F37:F38) -> 264509.44 | G39: =SUM(G37:G38) -> 14706.87 | H39: =SUM(H37:H38) -> -230503.06 | I39: =SUM(I37:I38) -> -470889.83 | J39: =SUM(J37:J38) -> -706180.8 | K39: =SUM(K37:K38) -> -936098.5 | L39: =SUM(L37:L38) -> -1160845.8 | M39: =SUM(M37:M38) -> -1380445 | ... BM39: =SUM(BM37:BM38) -> -6173679.7
B41: Fixed Assets | F41: =SUM(Assumptions!G192:G196) -> 0 | G41: =SUM(Assumptions!H192:H196) -> 0 | H41: =SUM(Assumptions!I192:I196) -> 0 | I41: =SUM(Assumptions!J192:J196) -> 0 | J41: =SUM(Assumptions!K192:K196) -> 0 | K41: =SUM(Assumptions!L192:L196) -> 0 | L41: =SUM(Assumptions!M192:M196) -> 0 | M41: =SUM(Assumptions!N192:N196) -> 0 | ... BM41: =SUM(Assumptions!BN192:BN196) -> 0
B42: Accumulated Depreciation | F42: =-SUM(Assumptions!G199:G202) -> 0 | G42: =-SUM(Assumptions!H199:H202) -> 0 | H42: =-SUM(Assumptions!I199:I202) -> 0 | I42: =-SUM(Assumptions!J199:J202) -> 0 | J42: =-SUM(Assumptions!K199:K202) -> 0 | K42: =-SUM(Assumptions!L199:L202) -> 0 | L42: =-SUM(Assumptions!M199:M202) -> 0 | M42: =-SUM(Assumptions!N199:N202) -> 0 | ... BM42: =-SUM(Assumptions!BN199:BN202) -> 0
B43: Total Assets | F43: =SUM(F39:F42) -> 264509.44 | G43: =SUM(G39:G42) -> 14706.87 | H43: =SUM(H39:H42) -> -230503.06 | I43: =SUM(I39:I42) -> -470889.83 | J43: =SUM(J39:J42) -> -706180.8 | K43: =SUM(K39:K42) -> -936098.5 | L43: =SUM(L39:L42) -> -1160845.8 | M43: =SUM(M39:M42) -> -1380445 | ... BM43: =SUM(BM39:BM42) -> -6173679.7
B45: Liabilities & Owner's Equity
B46: Liabilities
B47: Accounts payable | F47: =Assumptions!G206 -> 23506.806 | G47: =Assumptions!H206 -> 25920.574 | H47: =Assumptions!I206 -> 28446.694 | I47: =Assumptions!J206 -> 31096.437 | J47: =Assumptions!K206 -> 33889.044 | K47: =Assumptions!L206 -> 36833.205 | L47: =Assumptions!M206 -> 39758.853 | M47: =Assumptions!N206 -> 42669.805 | ... BM47: =Assumptions!BN206 -> 180917.08
B48: Total Liabilities | F48: =F47 -> 23506.806 | G48: =G47 -> 25920.574 | H48: =H47 -> 28446.694 | I48: =I47 -> 31096.437 | J48: =J47 -> 33889.044 | K48: =K47 -> 36833.205 | L48: =L47 -> 39758.853 | M48: =M47 -> 42669.805 | ... BM48: =BM47 -> 180917.08
B50: Equity | E50: Prev Cash
B51: Paid In Capital | E51: =Assumptions!C188 -> 500000 | F51: =E51 -> 500000 | G51: =Assumptions!H220+$E51 -> 500000 | H51: =Assumptions!I220+$E51 -> 500000 | I51: =Assumptions!J220+$E51 -> 500000 | J51: =Assumptions!K220+$E51 -> 500000 | K51: =Assumptions!L220+$E51 -> 500000 | L51: =Assumptions!M220+$E51 -> 500000 | M51: =Assumptions!N220+$E51 -> 500000 | N51: =Assumptions!O220+$E51 -> 500000 | ... BM51: =Assumptions!BN220+$E51 -> 500000
...
