Workbook

Sheet Overview
C2: YOUR LOGO HERE
C4: Financial Model
G5: Welcome! This template was created by Forecastr's team of Financial Analysts and Fractional CFOs to help our fellow founders create better financial models for their startups and small businesses. Forecastr is an out-of-the-box finance function for your business. We provide the tools and support you need to create an investor-grade financial model. Our analysts work with you every step of the way to build a model that's customized to fit your business, keep it up to date, and generate insightful reports to share with your investors and other stakeholders. ✔ Impress your investors ✔ Hit your growth targets ✔ Never run out of cash
C7: Your Website Link Here
C10: Table of Contents
C12: Assumptions
C14: Financials
I18: SCHEDULE A MODELING SESSION WITH A MEMBER OF OUR TEAM

Sheet Assumptions
B1: Year Counter | G1: 1 | H1: 1 | I1: 1 | J1: 1 | K1: 1 | L1: 1 | M1: 1 | N1: 1 | O1: 1 | P1: 1 | Q1: 1 | R1: 1 | S1: =G1+1 -> 2 | T1: =H1+1 -> 2 | U1: =I1+1 -> 2 | V1: =J1+1 -> 2 | W1: =K1+1 -> 2 | X1: =L1+1 -> 2 | Y1: =M1+1 -> 2 | Z1: =N1+1 -> 2 | ... BN1: =BB1+1 -> 5
B2: Year | G2: =YEAR(G4) -> 2026 | H2: =YEAR(H4) -> 2026 | I2: =YEAR(I4) -> 2026 | J2: =YEAR(J4) -> 2026 | K2: =YEAR(K4) -> 2026 | L2: =YEAR(L4) -> 2026 | M2: =YEAR(M4) -> 2026 | N2: =YEAR(N4) -> 2026 | ... BN2: =YEAR(BN4) -> 2031
B3: Month Counter | G3: 1 | H3: =G3+1 -> 2 | I3: =H3+1 -> 3 | J3: =I3+1 -> 4 | K3: =J3+1 -> 5 | L3: =K3+1 -> 6 | M3: =L3+1 -> 7 | N3: =M3+1 -> 8 | O3: =N3+1 -> 9 | ... BN3: =BM3+1 -> 60
B4: Date | G4: =eomonth(today(),0) -> 46081 | H4: =EOMONTH(G4,1) -> 46112 | I4: =EOMONTH(H4,1) -> 46142 | J4: =EOMONTH(I4,1) -> 46173 | K4: =EOMONTH(J4,1) -> 46203 | L4: =EOMONTH(K4,1) -> 46234 | M4: =EOMONTH(L4,1) -> 46265 | N4: =EOMONTH(M4,1) -> 46295 | O4: =EOMONTH(N4,1) -> 46326 | ... BN4: =EOMONTH(BM4,1) -> 47879
B6: Revenue - Custom Contracts:
B8: Custom Contracts
B9: Custom Contract 1 | D9: 5000 | G9: =D9 -> 5000 | H9: =G9 -> 5000 | I9: =H9 -> 5000 | J9: =I9 -> 5000 | K9: =J9 -> 5000 | L9: =K9 -> 5000 | M9: =L9 -> 5000 | N9: =M9 -> 5000 | O9: =N9 -> 5000 | ... BN9: =BM9 -> 5000
B10: Custom Contract 2 | D10: 4000 | G10: =D10 -> 4000 | H10: =G10 -> 4000 | I10: =H10 -> 4000 | J10: =I10 -> 4000 | K10: =J10 -> 4000 | L10: =K10 -> 4000 | M10: =L10 -> 4000 | N10: =M10 -> 4000 | O10: =N10 -> 4000 | ... BN10: =BM10 -> 4000
B11: Custom Contract 3 | D11: 3000 | G11: =D11 -> 3000 | H11: =G11 -> 3000 | I11: =H11 -> 3000 | J11: =I11 -> 3000 | K11: =J11 -> 3000 | L11: =K11 -> 3000 | M11: =L11 -> 3000 | N11: =M11 -> 3000 | O11: =N11 -> 3000 | ... BN11: =BM11 -> 3000
B12: Custom Contract 4 | D12: 2000 | G12: =D12 -> 2000 | H12: =G12 -> 2000 | I12: =H12 -> 2000 | J12: =I12 -> 2000 | K12: =J12 -> 2000 | L12: =K12 -> 2000 | M12: =L12 -> 2000 | N12: =M12 -> 2000 | O12: =N12 -> 2000 | ... BN12: =BM12 -> 2000
B13: Custom Contract 5 | D13: 1000 | G13: =D13 -> 1000 | H13: =G13 -> 1000 | I13: =H13 -> 1000 | J13: =I13 -> 1000 | K13: =J13 -> 1000 | L13: =K13 -> 1000 | M13: =L13 -> 1000 | N13: =M13 -> 1000 | O13: =N13 -> 1000 | ... BN13: =BM13 -> 1000
B14: Custom Contract 6 | D14: 500 | G14: =D14 -> 500 | H14: =G14 -> 500 | I14: =H14 -> 500 | J14: =I14 -> 500 | K14: =J14 -> 500 | L14: =K14 -> 500 | M14: =L14 -> 500 | N14: =M14 -> 500 | O14: =N14 -> 500 | ... BN14: =BM14 -> 500
B15: Revenue | G15: =sum(G9:G14) -> 15500 | H15: =sum(H9:H14) -> 15500 | I15: =sum(I9:I14) -> 15500 | J15: =sum(J9:J14) -> 15500 | K15: =sum(K9:K14) -> 15500 | L15: =sum(L9:L14) -> 15500 | M15: =sum(M9:M14) -> 15500 | N15: =sum(N9:N14) -> 15500 | ... BN15: =sum(BN9:BN14) -> 15500
B17: + ADD MORE
B20: People:
B22: Name | C22: Salary | D22: Benefits | E22: Start Date
B23: Person 1 | C23: 100000 | D23: 0.2 | E23: 43831 | G23: =IF(G$4>=$E23,($C23/12)*(1+$D23),0) -> 10000 | H23: =IF(H$4>=$E23,($C23/12)*(1+$D23),0) -> 10000 | I23: =IF(I$4>=$E23,($C23/12)*(1+$D23),0) -> 10000 | J23: =IF(J$4>=$E23,($C23/12)*(1+$D23),0) -> 10000 | K23: =IF(K$4>=$E23,($C23/12)*(1+$D23),0) -> 10000 | L23: =IF(L$4>=$E23,($C23/12)*(1+$D23),0) -> 10000 | M23: =IF(M$4>=$E23,($C23/12)*(1+$D23),0) -> 10000 | N23: =IF(N$4>=$E23,($C23/12)*(1+$D23),0) -> 10000 | ... BN23: =IF(BN$4>=$E23,($C23/12)*(1+$D23),0) -> 10000
B24: Person 2 | C24: 100000 | D24: 0.2 | E24: 43831 | G24: =IF(G$4>=$E24,($C24/12)*(1+$D24),0) -> 10000 | H24: =IF(H$4>=$E24,($C24/12)*(1+$D24),0) -> 10000 | I24: =IF(I$4>=$E24,($C24/12)*(1+$D24),0) -> 10000 | J24: =IF(J$4>=$E24,($C24/12)*(1+$D24),0) -> 10000 | K24: =IF(K$4>=$E24,($C24/12)*(1+$D24),0) -> 10000 | L24: =IF(L$4>=$E24,($C24/12)*(1+$D24),0) -> 10000 | M24: =IF(M$4>=$E24,($C24/12)*(1+$D24),0) -> 10000 | N24: =IF(N$4>=$E24,($C24/12)*(1+$D24),0) -> 10000 | ... BN24: =IF(BN$4>=$E24,($C24/12)*(1+$D24),0) -> 10000
B25: Person 3 | C25: 100000 | D25: 0.2 | E25: 44075 | G25: =IF(G$4>=$E25,($C25/12)*(1+$D25),0) -> 10000 | H25: =IF(H$4>=$E25,($C25/12)*(1+$D25),0) -> 10000 | I25: =IF(I$4>=$E25,($C25/12)*(1+$D25),0) -> 10000 | J25: =IF(J$4>=$E25,($C25/12)*(1+$D25),0) -> 10000 | K25: =IF(K$4>=$E25,($C25/12)*(1+$D25),0) -> 10000 | L25: =IF(L$4>=$E25,($C25/12)*(1+$D25),0) -> 10000 | M25: =IF(M$4>=$E25,($C25/12)*(1+$D25),0) -> 10000 | N25: =IF(N$4>=$E25,($C25/12)*(1+$D25),0) -> 10000 | ... BN25: =IF(BN$4>=$E25,($C25/12)*(1+$D25),0) -> 10000
B26: Person 4 | C26: 100000 | D26: 0.2 | E26: 43831 | G26: =IF(G$4>=$E26,($C26/12)*(1+$D26),0) -> 10000 | H26: =IF(H$4>=$E26,($C26/12)*(1+$D26),0) -> 10000 | I26: =IF(I$4>=$E26,($C26/12)*(1+$D26),0) -> 10000 | J26: =IF(J$4>=$E26,($C26/12)*(1+$D26),0) -> 10000 | K26: =IF(K$4>=$E26,($C26/12)*(1+$D26),0) -> 10000 | L26: =IF(L$4>=$E26,($C26/12)*(1+$D26),0) -> 10000 | M26: =IF(M$4>=$E26,($C26/12)*(1+$D26),0) -> 10000 | N26: =IF(N$4>=$E26,($C26/12)*(1+$D26),0) -> 10000 | ... BN26: =IF(BN$4>=$E26,($C26/12)*(1+$D26),0) -> 10000
B27: Person 5 | C27: 100000 | D27: 0.2 | E27: 43891 | G27: =IF(G$4>=$E27,($C27/12)*(1+$D27),0) -> 10000 | H27: =IF(H$4>=$E27,($C27/12)*(1+$D27),0) -> 10000 | I27: =IF(I$4>=$E27,($C27/12)*(1+$D27),0) -> 10000 | J27: =IF(J$4>=$E27,($C27/12)*(1+$D27),0) -> 10000 | K27: =IF(K$4>=$E27,($C27/12)*(1+$D27),0) -> 10000 | L27: =IF(L$4>=$E27,($C27/12)*(1+$D27),0) -> 10000 | M27: =IF(M$4>=$E27,($C27/12)*(1+$D27),0) -> 10000 | N27: =IF(N$4>=$E27,($C27/12)*(1+$D27),0) -> 10000 | ... BN27: =IF(BN$4>=$E27,($C27/12)*(1+$D27),0) -> 10000
B28: Person 6 | C28: 75000 | D28: 0.2 | E28: 43983 | G28: =IF(G$4>=$E28,($C28/12)*(1+$D28),0) -> 7500 | H28: =IF(H$4>=$E28,($C28/12)*(1+$D28),0) -> 7500 | I28: =IF(I$4>=$E28,($C28/12)*(1+$D28),0) -> 7500 | J28: =IF(J$4>=$E28,($C28/12)*(1+$D28),0) -> 7500 | K28: =IF(K$4>=$E28,($C28/12)*(1+$D28),0) -> 7500 | L28: =IF(L$4>=$E28,($C28/12)*(1+$D28),0) -> 7500 | M28: =IF(M$4>=$E28,($C28/12)*(1+$D28),0) -> 7500 | N28: =IF(N$4>=$E28,($C28/12)*(1+$D28),0) -> 7500 | ... BN28: =IF(BN$4>=$E28,($C28/12)*(1+$D28),0) -> 7500
B29: Person 7 | C29: 50000 | D29: 0.2 | E29: 44075 | G29: =IF(G$4>=$E29,($C29/12)*(1+$D29),0) -> 5000 | H29: =IF(H$4>=$E29,($C29/12)*(1+$D29),0) -> 5000 | I29: =IF(I$4>=$E29,($C29/12)*(1+$D29),0) -> 5000 | J29: =IF(J$4>=$E29,($C29/12)*(1+$D29),0) -> 5000 | K29: =IF(K$4>=$E29,($C29/12)*(1+$D29),0) -> 5000 | L29: =IF(L$4>=$E29,($C29/12)*(1+$D29),0) -> 5000 | M29: =IF(M$4>=$E29,($C29/12)*(1+$D29),0) -> 5000 | N29: =IF(N$4>=$E29,($C29/12)*(1+$D29),0) -> 5000 | ... BN29: =IF(BN$4>=$E29,($C29/12)*(1+$D29),0) -> 5000
B30: Person 8 | C30: 80000 | D30: 0.2 | E30: 44166 | G30: =IF(G$4>=$E30,($C30/12)*(1+$D30),0) -> 8000 | H30: =IF(H$4>=$E30,($C30/12)*(1+$D30),0) -> 8000 | I30: =IF(I$4>=$E30,($C30/12)*(1+$D30),0) -> 8000 | J30: =IF(J$4>=$E30,($C30/12)*(1+$D30),0) -> 8000 | K30: =IF(K$4>=$E30,($C30/12)*(1+$D30),0) -> 8000 | L30: =IF(L$4>=$E30,($C30/12)*(1+$D30),0) -> 8000 | M30: =IF(M$4>=$E30,($C30/12)*(1+$D30),0) -> 8000 | N30: =IF(N$4>=$E30,($C30/12)*(1+$D30),0) -> 8000 | ... BN30: =IF(BN$4>=$E30,($C30/12)*(1+$D30),0) -> 8000
B31: Person 9 | C31: 90000 | D31: 0.2 | E31: 44256 | G31: =IF(G$4>=$E31,($C31/12)*(1+$D31),0) -> 9000 | H31: =IF(H$4>=$E31,($C31/12)*(1+$D31),0) -> 9000 | I31: =IF(I$4>=$E31,($C31/12)*(1+$D31),0) -> 9000 | J31: =IF(J$4>=$E31,($C31/12)*(1+$D31),0) -> 9000 | K31: =IF(K$4>=$E31,($C31/12)*(1+$D31),0) -> 9000 | L31: =IF(L$4>=$E31,($C31/12)*(1+$D31),0) -> 9000 | M31: =IF(M$4>=$E31,($C31/12)*(1+$D31),0) -> 9000 | N31: =IF(N$4>=$E31,($C31/12)*(1+$D31),0) -> 9000 | ... BN31: =IF(BN$4>=$E31,($C31/12)*(1+$D31),0) -> 9000
B32: Person 10 | C32: 45000 | D32: 0.2 | E32: 44348 | G32: =IF(G$4>=$E32,($C32/12)*(1+$D32),0) -> 4500 | H32: =IF(H$4>=$E32,($C32/12)*(1+$D32),0) -> 4500 | I32: =IF(I$4>=$E32,($C32/12)*(1+$D32),0) -> 4500 | J32: =IF(J$4>=$E32,($C32/12)*(1+$D32),0) -> 4500 | K32: =IF(K$4>=$E32,($C32/12)*(1+$D32),0) -> 4500 | L32: =IF(L$4>=$E32,($C32/12)*(1+$D32),0) -> 4500 | M32: =IF(M$4>=$E32,($C32/12)*(1+$D32),0) -> 4500 | N32: =IF(N$4>=$E32,($C32/12)*(1+$D32),0) -> 4500 | ... BN32: =IF(BN$4>=$E32,($C32/12)*(1+$D32),0) -> 4500
B33: Person 11 | C33: 100000 | D33: 0.2 | E33: 43831 | G33: =IF(G$4>=$E33,($C33/12)*(1+$D33),0) -> 10000 | H33: =IF(H$4>=$E33,($C33/12)*(1+$D33),0) -> 10000 | I33: =IF(I$4>=$E33,($C33/12)*(1+$D33),0) -> 10000 | J33: =IF(J$4>=$E33,($C33/12)*(1+$D33),0) -> 10000 | K33: =IF(K$4>=$E33,($C33/12)*(1+$D33),0) -> 10000 | L33: =IF(L$4>=$E33,($C33/12)*(1+$D33),0) -> 10000 | M33: =IF(M$4>=$E33,($C33/12)*(1+$D33),0) -> 10000 | N33: =IF(N$4>=$E33,($C33/12)*(1+$D33),0) -> 10000 | ... BN33: =IF(BN$4>=$E33,($C33/12)*(1+$D33),0) -> 10000
B34: Person 12 | C34: 100000 | D34: 0.2 | E34: 43831 | G34: =IF(G$4>=$E34,($C34/12)*(1+$D34),0) -> 10000 | H34: =IF(H$4>=$E34,($C34/12)*(1+$D34),0) -> 10000 | I34: =IF(I$4>=$E34,($C34/12)*(1+$D34),0) -> 10000 | J34: =IF(J$4>=$E34,($C34/12)*(1+$D34),0) -> 10000 | K34: =IF(K$4>=$E34,($C34/12)*(1+$D34),0) -> 10000 | L34: =IF(L$4>=$E34,($C34/12)*(1+$D34),0) -> 10000 | M34: =IF(M$4>=$E34,($C34/12)*(1+$D34),0) -> 10000 | N34: =IF(N$4>=$E34,($C34/12)*(1+$D34),0) -> 10000 | ... BN34: =IF(BN$4>=$E34,($C34/12)*(1+$D34),0) -> 10000
... B47: Person 25 | C47: 45000 | D47: 0.2 | E47: 44348 | G47: =IF(G$4>=$E47,($C47/12)*(1+$D47),0) -> 4500 | H47: =IF(H$4>=$E47,($C47/12)*(1+$D47),0) -> 4500 | I47: =IF(I$4>=$E47,($C47/12)*(1+$D47),0) -> 4500 | J47: =IF(J$4>=$E47,($C47/12)*(1+$D47),0) -> 4500 | K47: =IF(K$4>=$E47,($C47/12)*(1+$D47),0) -> 4500 | L47: =IF(L$4>=$E47,($C47/12)*(1+$D47),0) -> 4500 | M47: =IF(M$4>=$E47,($C47/12)*(1+$D47),0) -> 4500 | N47: =IF(N$4>=$E47,($C47/12)*(1+$D47),0) -> 4500 | ... BN47: =IF(BN$4>=$E47,($C47/12)*(1+$D47),0) -> 4500
B49: Expenses:
B51: Costs of Goods Sold | C51: % Revenue
B52: Database & Hosting | C52: 0.02 | G52: =Financials!F$8*$C52 -> 310 | H52: =Financials!G$8*$C52 -> 310 | I52: =Financials!H$8*$C52 -> 310 | J52: =Financials!I$8*$C52 -> 310 | K52: =Financials!J$8*$C52 -> 310 | L52: =Financials!K$8*$C52 -> 310 | M52: =Financials!L$8*$C52 -> 310 | N52: =Financials!M$8*$C52 -> 310 | ... BN52: =Financials!BM$8*$C52 -> 310
B53: Payment Processing | C53: 0.03 | G53: =Financials!F$8*$C53 -> 465 | H53: =Financials!G$8*$C53 -> 465 | I53: =Financials!H$8*$C53 -> 465 | J53: =Financials!I$8*$C53 -> 465 | K53: =Financials!J$8*$C53 -> 465 | L53: =Financials!K$8*$C53 -> 465 | M53: =Financials!L$8*$C53 -> 465 | N53: =Financials!M$8*$C53 -> 465 | ... BN53: =Financials!BM$8*$C53 -> 465
B54: Other | C54: 0.05 | G54: =Financials!F$8*$C54 -> 775 | H54: =Financials!G$8*$C54 -> 775 | I54: =Financials!H$8*$C54 -> 775 | J54: =Financials!I$8*$C54 -> 775 | K54: =Financials!J$8*$C54 -> 775 | L54: =Financials!K$8*$C54 -> 775 | M54: =Financials!L$8*$C54 -> 775 | N54: =Financials!M$8*$C54 -> 775 | ... BN54: =Financials!BM$8*$C54 -> 775
B55: COGS 1 | C55: 0.05 | G55: =Financials!F$8*$C55 -> 775 | H55: =Financials!G$8*$C55 -> 775 | I55: =Financials!H$8*$C55 -> 775 | J55: =Financials!I$8*$C55 -> 775 | K55: =Financials!J$8*$C55 -> 775 | L55: =Financials!K$8*$C55 -> 775 | M55: =Financials!L$8*$C55 -> 775 | N55: =Financials!M$8*$C55 -> 775 | ... BN55: =Financials!BM$8*$C55 -> 775
B56: COGS 2 | C56: 0.05 | G56: =Financials!F$8*$C56 -> 775 | H56: =Financials!G$8*$C56 -> 775 | I56: =Financials!H$8*$C56 -> 775 | J56: =Financials!I$8*$C56 -> 775 | K56: =Financials!J$8*$C56 -> 775 | L56: =Financials!K$8*$C56 -> 775 | M56: =Financials!L$8*$C56 -> 775 | N56: =Financials!M$8*$C56 -> 775 | ... BN56: =Financials!BM$8*$C56 -> 775
B57: COGS 3 | C57: 0.05 | G57: =Financials!F$8*$C57 -> 775 | H57: =Financials!G$8*$C57 -> 775 | I57: =Financials!H$8*$C57 -> 775 | J57: =Financials!I$8*$C57 -> 775 | K57: =Financials!J$8*$C57 -> 775 | L57: =Financials!K$8*$C57 -> 775 | M57: =Financials!L$8*$C57 -> 775 | N57: =Financials!M$8*$C57 -> 775 | ... BN57: =Financials!BM$8*$C57 -> 775
B58: COGS 4 | C58: 0.05 | G58: =Financials!F$8*$C58 -> 775 | H58: =Financials!G$8*$C58 -> 775 | I58: =Financials!H$8*$C58 -> 775 | J58: =Financials!I$8*$C58 -> 775 | K58: =Financials!J$8*$C58 -> 775 | L58: =Financials!K$8*$C58 -> 775 | M58: =Financials!L$8*$C58 -> 775 | N58: =Financials!M$8*$C58 -> 775 | ... BN58: =Financials!BM$8*$C58 -> 775
B59: COGS 5 | C59: 0.05 | G59: =Financials!F$8*$C59 -> 775 | H59: =Financials!G$8*$C59 -> 775 | I59: =Financials!H$8*$C59 -> 775 | J59: =Financials!I$8*$C59 -> 775 | K59: =Financials!J$8*$C59 -> 775 | L59: =Financials!K$8*$C59 -> 775 | M59: =Financials!L$8*$C59 -> 775 | N59: =Financials!M$8*$C59 -> 775 | ... BN59: =Financials!BM$8*$C59 -> 775
B60: Total | G60: =sum(G52:G59) -> 5425 | H60: =sum(H52:H59) -> 5425 | I60: =sum(I52:I59) -> 5425 | J60: =sum(J52:J59) -> 5425 | K60: =sum(K52:K59) -> 5425 | L60: =sum(L52:L59) -> 5425 | M60: =sum(M52:M59) -> 5425 | N60: =sum(N52:N59) -> 5425 | ... BN60: =sum(BN52:BN59) -> 5425
...

Sheet Financials
B1: Year Counter | F1: 1 | G1: 1 | H1: 1 | I1: 1 | J1: 1 | K1: 1 | L1: 1 | M1: 1 | N1: 1 | O1: 1 | P1: 1 | Q1: 1 | R1: =F1+1 -> 2 | S1: =G1+1 -> 2 | T1: =H1+1 -> 2 | U1: =I1+1 -> 2 | V1: =J1+1 -> 2 | W1: =K1+1 -> 2 | X1: =L1+1 -> 2 | Y1: =M1+1 -> 2 | ... BM1: =BA1+1 -> 5
B2: Year | F2: =YEAR(F4) -> 2026 | G2: =YEAR(G4) -> 2026 | H2: =YEAR(H4) -> 2026 | I2: =YEAR(I4) -> 2026 | J2: =YEAR(J4) -> 2026 | K2: =YEAR(K4) -> 2026 | L2: =YEAR(L4) -> 2026 | M2: =YEAR(M4) -> 2026 | ... BM2: =YEAR(BM4) -> 2031
B3: Month Counter | F3: 1 | G3: =F3+1 -> 2 | H3: =G3+1 -> 3 | I3: =H3+1 -> 4 | J3: =I3+1 -> 5 | K3: =J3+1 -> 6 | L3: =K3+1 -> 7 | M3: =L3+1 -> 8 | N3: =M3+1 -> 9 | ... BM3: =BL3+1 -> 60
B4: Date | F4: =Assumptions!G4 -> 46081 | G4: =EOMONTH(F4,1) -> 46112 | H4: =EOMONTH(G4,1) -> 46142 | I4: =EOMONTH(H4,1) -> 46173 | J4: =EOMONTH(I4,1) -> 46203 | K4: =EOMONTH(J4,1) -> 46234 | L4: =EOMONTH(K4,1) -> 46265 | M4: =EOMONTH(L4,1) -> 46295 | N4: =EOMONTH(M4,1) -> 46326 | ... BM4: =EOMONTH(BL4,1) -> 47879
B6: Income Statement:
B8: Revenue | F8: =Assumptions!G15 -> 15500 | G8: =Assumptions!H15 -> 15500 | H8: =Assumptions!I15 -> 15500 | I8: =Assumptions!J15 -> 15500 | J8: =Assumptions!K15 -> 15500 | K8: =Assumptions!L15 -> 15500 | L8: =Assumptions!M15 -> 15500 | M8: =Assumptions!N15 -> 15500 | ... BM8: =Assumptions!BN15 -> 15500
B10: COGS | F10: =Assumptions!G60 -> 5425 | G10: =Assumptions!H60 -> 5425 | H10: =Assumptions!I60 -> 5425 | I10: =Assumptions!J60 -> 5425 | J10: =Assumptions!K60 -> 5425 | K10: =Assumptions!L60 -> 5425 | L10: =Assumptions!M60 -> 5425 | M10: =Assumptions!N60 -> 5425 | ... BN10: =Assumptions!BO60
B12: Gross Profit | F12: =F8-F10 -> 10075 | G12: =G8-G10 -> 10075 | H12: =H8-H10 -> 10075 | I12: =I8-I10 -> 10075 | J12: =J8-J10 -> 10075 | K12: =K8-K10 -> 10075 | L12: =L8-L10 -> 10075 | M12: =M8-M10 -> 10075 | ... BM12: =BM8-BM10 -> 10075
B13: Gross Margin | F13: =F12/F8 -> 0.65 | G13: =G12/G8 -> 0.65 | H13: =H12/H8 -> 0.65 | I13: =I12/I8 -> 0.65 | J13: =J12/J8 -> 0.65 | K13: =K12/K8 -> 0.65 | L13: =L12/L8 -> 0.65 | M13: =M12/M8 -> 0.65 | ... BM13: =BM12/BM8 -> 0.65
B15: Operating Expenses
B16: Salaries & Benefits | F16: =SUM(Assumptions!G23:G47) -> 202000 | G16: =SUM(Assumptions!H23:H47) -> 202000 | H16: =SUM(Assumptions!I23:I47) -> 202000 | I16: =SUM(Assumptions!J23:J47) -> 202000 | J16: =SUM(Assumptions!K23:K47) -> 202000 | K16: =SUM(Assumptions!L23:L47) -> 202000 | L16: =SUM(Assumptions!M23:M47) -> 202000 | M16: =SUM(Assumptions!N23:N47) -> 202000 | ... BM16: =SUM(Assumptions!BN23:BN47) -> 202000
B17: =Assumptions!B62 -> General & Admin | F17: =sum(Assumptions!G63:G70) -> 20000 | G17: =sum(Assumptions!H63:H70) -> 20000 | H17: =sum(Assumptions!I63:I70) -> 20000 | I17: =sum(Assumptions!J63:J70) -> 20000 | J17: =sum(Assumptions!K63:K70) -> 20000 | K17: =sum(Assumptions!L63:L70) -> 20000 | L17: =sum(Assumptions!M63:M70) -> 20000 | M17: =sum(Assumptions!N63:N70) -> 20000 | ... BM17: =sum(Assumptions!BN63:BN70) -> 20000
B18: =Assumptions!B73 -> Sales & Marketing | F18: =sum(Assumptions!G74:G75) -> 11240 | G18: =sum(Assumptions!H74:H75) -> 11240 | H18: =sum(Assumptions!I74:I75) -> 11240 | I18: =sum(Assumptions!J74:J75) -> 11240 | J18: =sum(Assumptions!K74:K75) -> 11240 | K18: =sum(Assumptions!L74:L75) -> 11240 | L18: =sum(Assumptions!M74:M75) -> 11240 | M18: =sum(Assumptions!N74:N75) -> 11240 | ... BM18: =sum(Assumptions!BN74:BN75) -> 11240
B19: =Assumptions!B78 -> Professional Fees | F19: =SUM(Assumptions!G79:G81) -> 5000 | G19: =SUM(Assumptions!H79:H81) -> 5000 | H19: =SUM(Assumptions!I79:I81) -> 5000 | I19: =SUM(Assumptions!J79:J81) -> 5000 | J19: =SUM(Assumptions!K79:K81) -> 5000 | K19: =SUM(Assumptions!L79:L81) -> 5000 | L19: =SUM(Assumptions!M79:M81) -> 5000 | M19: =SUM(Assumptions!N79:N81) -> 5000 | ... BM19: =SUM(Assumptions!BN79:BN81) -> 5000
B20: =Assumptions!B84 -> Other | F20: =Assumptions!G85 -> 1550 | G20: =Assumptions!H85 -> 1550 | H20: =Assumptions!I85 -> 1550 | I20: =Assumptions!J85 -> 1550 | J20: =Assumptions!K85 -> 1550 | K20: =Assumptions!L85 -> 1550 | L20: =Assumptions!M85 -> 1550 | M20: =Assumptions!N85 -> 1550 | ... BM20: =Assumptions!BN85 -> 1550
B21: Total Operating Expenses | F21: =SUM(F16:F20) -> 239790 | G21: =SUM(G16:G20) -> 239790 | H21: =SUM(H16:H20) -> 239790 | I21: =SUM(I16:I20) -> 239790 | J21: =SUM(J16:J20) -> 239790 | K21: =SUM(K16:K20) -> 239790 | L21: =SUM(L16:L20) -> 239790 | M21: =SUM(M16:M20) -> 239790 | ... BM21: =SUM(BM16:BM20) -> 239790
B23: EBITDA | F23: =F12-F21 -> -229715 | G23: =G12-G21 -> -229715 | H23: =H12-H21 -> -229715 | I23: =I12-I21 -> -229715 | J23: =J12-J21 -> -229715 | K23: =K12-K21 -> -229715 | L23: =L12-L21 -> -229715 | M23: =M12-M21 -> -229715 | ... BM23: =BM12-BM21 -> -229715
B24: Depreciation | F24: =SUM(Assumptions!G106:G109)-sum(Assumptions!E106:E109) -> 0 | G24: =SUM(Assumptions!H106:H109)-sum(Assumptions!G106:G109) -> 0 | H24: =SUM(Assumptions!I106:I109)-sum(Assumptions!H106:H109) -> 0 | I24: =SUM(Assumptions!J106:J109)-sum(Assumptions!I106:I109) -> 0 | J24: =SUM(Assumptions!K106:K109)-sum(Assumptions!J106:J109) -> 0 | K24: =SUM(Assumptions!L106:L109)-sum(Assumptions!K106:K109) -> 0 | L24: =SUM(Assumptions!M106:M109)-sum(Assumptions!L106:L109) -> 0 | M24: =SUM(Assumptions!N106:N109)-sum(Assumptions!M106:M109) -> 0 | N24: =SUM(Assumptions!O106:O109)-sum(Assumptions!N106:N109) -> 0 | ... BM24: =SUM(Assumptions!BN106:BN109)-sum(Assumptions!BM106:BM109) -> 0
B25: EBIT | F25: =F23-F24 -> -229715 | G25: =G23-G24 -> -229715 | H25: =H23-H24 -> -229715 | I25: =I23-I24 -> -229715 | J25: =J23-J24 -> -229715 | K25: =K23-K24 -> -229715 | L25: =L23-L24 -> -229715 | M25: =M23-M24 -> -229715 | ... BM25: =BM23-BM24 -> -229715
B26: Taxes | F26: =IF(F25>0,F25*Assumptions!$C$87,0) -> 0 | G26: =IF(G25>0,G25*Assumptions!$C$87,0) -> 0 | H26: =IF(H25>0,H25*Assumptions!$C$87,0) -> 0 | I26: =IF(I25>0,I25*Assumptions!$C$87,0) -> 0 | J26: =IF(J25>0,J25*Assumptions!$C$87,0) -> 0 | K26: =IF(K25>0,K25*Assumptions!$C$87,0) -> 0 | L26: =IF(L25>0,L25*Assumptions!$C$87,0) -> 0 | M26: =IF(M25>0,M25*Assumptions!$C$87,0) -> 0 | ... BM26: =IF(BM25>0,BM25*Assumptions!$C$87,0) -> 0
B27: Net Income | F27: =F25-F26 -> -229715 | G27: =G25-G26 -> -229715 | H27: =H25-H26 -> -229715 | I27: =I25-I26 -> -229715 | J27: =J25-J26 -> -229715 | K27: =K25-K26 -> -229715 | L27: =L25-L26 -> -229715 | M27: =M25-M26 -> -229715 | ... BM27: =BM25-BM26 -> -229715
B28: Net Margin | F28: =F27/F8 -> -14.820323 | G28: =G27/G8 -> -14.820323 | H28: =H27/H8 -> -14.820323 | I28: =I27/I8 -> -14.820323 | J28: =J27/J8 -> -14.820323 | K28: =K27/K8 -> -14.820323 | L28: =L27/L8 -> -14.820323 | M28: =M27/M8 -> -14.820323 | ... BM28: =BM27/BM8 -> -14.820323
B30: Balance Sheet:
B32: Assets
B33: Current Assets
B34: Cash | F34: =F77 -> 284142.5 | G34: =G77 -> 54427.5 | H34: =H77 -> -175287.5 | I34: =I77 -> -405002.5 | J34: =J77 -> -634717.5 | K34: =K77 -> -864432.5 | L34: =L77 -> -1094147.5 | M34: =M77 -> -1323862.5 | ... BM34: =BM77 -> -13269042
B35: Accounts Receivable | F35: =Assumptions!G97 -> 7750 | G35: =Assumptions!H97 -> 7750 | H35: =Assumptions!I97 -> 7750 | I35: =Assumptions!J97 -> 7750 | J35: =Assumptions!K97 -> 7750 | K35: =Assumptions!L97 -> 7750 | L35: =Assumptions!M97 -> 7750 | M35: =Assumptions!N97 -> 7750 | ... BM35: =Assumptions!BN97 -> 7750
B36: Total Current Assets | F36: =SUM(F34:F35) -> 291892.5 | G36: =SUM(G34:G35) -> 62177.5 | H36: =SUM(H34:H35) -> -167537.5 | I36: =SUM(I34:I35) -> -397252.5 | J36: =SUM(J34:J35) -> -626967.5 | K36: =SUM(K34:K35) -> -856682.5 | L36: =SUM(L34:L35) -> -1086397.5 | M36: =SUM(M34:M35) -> -1316112.5 | ... BM36: =SUM(BM34:BM35) -> -13261292
B38: Fixed Assets | F38: =SUM(Assumptions!G99:G103) -> 0 | G38: =SUM(Assumptions!H99:H103) -> 0 | H38: =SUM(Assumptions!I99:I103) -> 0 | I38: =SUM(Assumptions!J99:J103) -> 0 | J38: =SUM(Assumptions!K99:K103) -> 0 | K38: =SUM(Assumptions!L99:L103) -> 0 | L38: =SUM(Assumptions!M99:M103) -> 0 | M38: =SUM(Assumptions!N99:N103) -> 0 | ... BM38: =SUM(Assumptions!BN99:BN103) -> 0
B39: Accumulated Depreciation | F39: =-SUM(Assumptions!G106:G109) -> 0 | G39: =-SUM(Assumptions!H106:H109) -> 0 | H39: =-SUM(Assumptions!I106:I109) -> 0 | I39: =-SUM(Assumptions!J106:J109) -> 0 | J39: =-SUM(Assumptions!K106:K109) -> 0 | K39: =-SUM(Assumptions!L106:L109) -> 0 | L39: =-SUM(Assumptions!M106:M109) -> 0 | M39: =-SUM(Assumptions!N106:N109) -> 0 | ... BM39: =-SUM(Assumptions!BN106:BN109) -> 0
B40: Total Assets | F40: =SUM(F36:F39) -> 291892.5 | G40: =SUM(G36:G39) -> 62177.5 | H40: =SUM(H36:H39) -> -167537.5 | I40: =SUM(I36:I39) -> -397252.5 | J40: =SUM(J36:J39) -> -626967.5 | K40: =SUM(K36:K39) -> -856682.5 | L40: =SUM(L36:L39) -> -1086397.5 | M40: =SUM(M36:M39) -> -1316112.5 | ... BM40: =SUM(BM36:BM39) -> -13261292
B42: Liabilities & Owner's Equity
B43: Liabilities
B44: Accounts payable | F44: =Assumptions!G113 -> 21607.5 | G44: =Assumptions!H113 -> 21607.5 | H44: =Assumptions!I113 -> 21607.5 | I44: =Assumptions!J113 -> 21607.5 | J44: =Assumptions!K113 -> 21607.5 | K44: =Assumptions!L113 -> 21607.5 | L44: =Assumptions!M113 -> 21607.5 | M44: =Assumptions!N113 -> 21607.5 | ... BM44: =Assumptions!BN113 -> 21607.5
B45: Total Liabilities | F45: =F44 -> 21607.5 | G45: =G44 -> 21607.5 | H45: =H44 -> 21607.5 | I45: =I44 -> 21607.5 | J45: =J44 -> 21607.5 | K45: =K44 -> 21607.5 | L45: =L44 -> 21607.5 | M45: =M44 -> 21607.5 | ... BM45: =BM44 -> 21607.5
B47: Equity | E47: Prev Cash
B48: Paid In Capital | E48: =Assumptions!C95 -> 500000 | F48: =E48 -> 500000 | G48: =Assumptions!H127+$E48 -> 500000 | H48: =Assumptions!I127+$E48 -> 500000 | I48: =Assumptions!J127+$E48 -> 500000 | J48: =Assumptions!K127+$E48 -> 500000 | K48: =Assumptions!L127+$E48 -> 500000 | L48: =Assumptions!M127+$E48 -> 500000 | M48: =Assumptions!N127+$E48 -> 500000 | N48: =Assumptions!O127+$E48 -> 500000 | ... BM48: =Assumptions!BN127+$E48 -> 500000
B49: Accumulated Retained Earnings | F49: =E49+F27 -> -229715 | G49: =F49+G27 -> -459430 | H49: =G49+H27 -> -689145 | I49: =H49+I27 -> -918860 | J49: =I49+J27 -> -1148575 | K49: =J49+K27 -> -1378290 | L49: =K49+L27 -> -1608005 | M49: =L49+M27 -> -1837720 | ... BM49: =BL49+BM27 -> -13782900
B50: Total Equity | F50: =SUM(F48:F49) -> 270285 | G50: =SUM(G48:G49) -> 40570 | H50: =SUM(H48:H49) -> -189145 | I50: =SUM(I48:I49) -> -418860 | J50: =SUM(J48:J49) -> -648575 | K50: =SUM(K48:K49) -> -878290 | L50: =SUM(L48:L49) -> -1108005 | M50: =SUM(M48:M49) -> -1337720 | ... BM50: =SUM(BM48:BM49) -> -13282900
B52: Total Liabilities & Owner's Equity | F52: =F50+F45 -> 291892.5 | G52: =G50+G45 -> 62177.5 | H52: =H50+H45 -> -167537.5 | I52: =I50+I45 -> -397252.5 | J52: =J50+J45 -> -626967.5 | K52: =K50+K45 -> -856682.5 | L52: =L50+L45 -> -1086397.5 | M52: =M50+M45 -> -1316112.5 | ... BM52: =BM50+BM45 -> -13261292
...
