Workbook

Sheet Overview
C2: YOUR LOGO HERE
C4: Financial Model
G5: Welcome! This template was created by Forecastr's team of Financial Analysts and Fractional CFOs to help our fellow founders create better financial models for their startups and small businesses. Forecastr is an out-of-the-box finance function for your business. We provide the tools and support you need to create an investor-grade financial model. Our analysts work with you every step of the way to build a model that's customized to fit your business, keep it up to date, and generate insightful reports to share with your investors and other stakeholders. ✔ Impress your investors ✔ Hit your growth targets ✔ Never run out of cash
C7: Your Website Link Here
C10: Table of Contents
C12: Assumptions
C14: Financials
I18: SCHEDULE A MODELING SESSION WITH A MEMBER OF OUR TEAM

Sheet Assumptions
B1: Year Counter | G1: 1 | H1: 1 | I1: 1 | J1: 1 | K1: 1 | L1: 1 | M1: 1 | N1: 1 | O1: 1 | P1: 1 | Q1: 1 | R1: 1 | S1: =G1+1 -> 2 | T1: =H1+1 -> 2 | U1: =I1+1 -> 2 | V1: =J1+1 -> 2 | W1: =K1+1 -> 2 | X1: =L1+1 -> 2 | Y1: =M1+1 -> 2 | Z1: =N1+1 -> 2 | ... BN1: =BB1+1 -> 5
B2: Year | G2: =YEAR(G4) -> 2026 | H2: =YEAR(H4) -> 2026 | I2: =YEAR(I4) -> 2026 | J2: =YEAR(J4) -> 2026 | K2: =YEAR(K4) -> 2026 | L2: =YEAR(L4) -> 2026 | M2: =YEAR(M4) -> 2026 | N2: =YEAR(N4) -> 2026 | ... BN2: =YEAR(BN4) -> 2031
B3: Month Counter | G3: 1 | H3: =G3+1 -> 2 | I3: =H3+1 -> 3 | J3: =I3+1 -> 4 | K3: =J3+1 -> 5 | L3: =K3+1 -> 6 | M3: =L3+1 -> 7 | N3: =M3+1 -> 8 | O3: =N3+1 -> 9 | ... BN3: =BM3+1 -> 60
B4: Date | G4: =eomonth(today(),0) -> 46081 | H4: =EOMONTH(G4,1) -> 46112 | I4: =EOMONTH(H4,1) -> 46142 | J4: =EOMONTH(I4,1) -> 46173 | K4: =EOMONTH(J4,1) -> 46203 | L4: =EOMONTH(K4,1) -> 46234 | M4: =EOMONTH(L4,1) -> 46265 | N4: =EOMONTH(M4,1) -> 46295 | O4: =EOMONTH(N4,1) -> 46326 | ... BN4: =EOMONTH(BM4,1) -> 47879
B6: Customer Acquisition:
B8: Build Customer Acquisition Channels
B10: Organic / Word of Mouth
B11: App Traffic | D11: 1000 | G11: =D11 -> 1000 | H11: =G11 -> 1000 | I11: =H11 -> 1000 | J11: =I11 -> 1000 | K11: =J11 -> 1000 | L11: =K11 -> 1000 | M11: =L11 -> 1000 | N11: =M11 -> 1000 | O11: =N11 -> 1000 | ... BN11: =BM11 -> 1000
B12: Conversion Rate | D12: 0.05 | G12: =D12 -> 0.05 | H12: =G12 -> 0.05 | I12: =H12 -> 0.05 | J12: =I12 -> 0.05 | K12: =J12 -> 0.05 | L12: =K12 -> 0.05 | M12: =L12 -> 0.05 | N12: =M12 -> 0.05 | O12: =N12 -> 0.05 | ... BN12: =BM12 -> 0.05
B13: New Customers | G13: =G11*G12 -> 50 | H13: =H11*H12 -> 50 | I13: =I11*I12 -> 50 | J13: =J11*J12 -> 50 | K13: =K11*K12 -> 50 | L13: =L11*L12 -> 50 | M13: =M11*M12 -> 50 | N13: =N11*N12 -> 50 | ... BN13: =BN11*BN12 -> 50
B15: Paid Advertising
B16: Budget per Month | D16: 5000 | G16: =D16 -> 5000 | H16: =G16 -> 5000 | I16: =H16 -> 5000 | J16: =I16 -> 5000 | K16: =J16 -> 5000 | L16: =K16 -> 5000 | M16: =L16 -> 5000 | N16: =M16 -> 5000 | O16: =N16 -> 5000 | ... BN16: =BM16 -> 5000
B17: Average CPC | D17: 2 | G17: =D17 -> 2 | H17: =G17 -> 2 | I17: =H17 -> 2 | J17: =I17 -> 2 | K17: =J17 -> 2 | L17: =K17 -> 2 | M17: =L17 -> 2 | N17: =M17 -> 2 | O17: =N17 -> 2 | ... BN17: =BM17 -> 2
B18: Conversion Rate | D18: 0.05 | G18: =D18 -> 0.05 | H18: =G18 -> 0.05 | I18: =H18 -> 0.05 | J18: =I18 -> 0.05 | K18: =J18 -> 0.05 | L18: =K18 -> 0.05 | M18: =L18 -> 0.05 | N18: =M18 -> 0.05 | O18: =N18 -> 0.05 | ... BN18: =BM18 -> 0.05
B19: New Customers | G19: =(G16/G17)*G18 -> 125 | H19: =(H16/H17)*H18 -> 125 | I19: =(I16/I17)*I18 -> 125 | J19: =(J16/J17)*J18 -> 125 | K19: =(K16/K17)*K18 -> 125 | L19: =(L16/L17)*L18 -> 125 | M19: =(M16/M17)*M18 -> 125 | N19: =(N16/N17)*N18 -> 125 | ... BN19: =(BN16/BN17)*BN18 -> 125
B21: Affiliates
B22: Number of Affiliates | D22: 5 | G22: =D22 -> 5 | H22: =G22 -> 5 | I22: =H22 -> 5 | J22: =I22 -> 5 | K22: =J22 -> 5 | L22: =K22 -> 5 | M22: =L22 -> 5 | N22: =M22 -> 5 | O22: =N22 -> 5 | ... BN22: =BM22 -> 5
B23: New Monthly Leads per Affiliate | D23: 50 | G23: =D23 -> 50 | H23: =G23 -> 50 | I23: =H23 -> 50 | J23: =I23 -> 50 | K23: =J23 -> 50 | L23: =K23 -> 50 | M23: =L23 -> 50 | N23: =M23 -> 50 | O23: =N23 -> 50 | ... BN23: =BM23 -> 50
B24: Conversion Rate | D24: 0.05 | G24: =D24 -> 0.05 | H24: =G24 -> 0.05 | I24: =H24 -> 0.05 | J24: =I24 -> 0.05 | K24: =J24 -> 0.05 | L24: =K24 -> 0.05 | M24: =L24 -> 0.05 | N24: =M24 -> 0.05 | O24: =N24 -> 0.05 | ... BN24: =BM24 -> 0.05
B25: New Customers | G25: =G22*G23*G24 -> 12.5 | H25: =H22*H23*H24 -> 12.5 | I25: =I22*I23*I24 -> 12.5 | J25: =J22*J23*J24 -> 12.5 | K25: =K22*K23*K24 -> 12.5 | L25: =L22*L23*L24 -> 12.5 | M25: =M22*M23*M24 -> 12.5 | N25: =N22*N23*N24 -> 12.5 | ... BN25: =BN22*BN23*BN24 -> 12.5
B27: Transactional
B28: Days Selling | D28: 1 | G28: 1 | H28: 0 | I28: 0 | J28: 0 | K28: 0 | L28: 0 | M28: 0 | N28: 0 | O28: 0 | P28: 0 | Q28: 0 | R28: 0 | S28: 0 | T28: 0 | U28: 0 | V28: 0 | W28: 0 | X28: 0 | Y28: 0 | Z28: 0 | AA28: 0 | AB28: 0 | AC28: 0 | AD28: 0 | AE28: 0 | AF28: 0 | AG28: 0 | AH28: 0 | AI28: 0 | AJ28: 0 | AK28: 0 | AL28: 0 | AM28: 0 | AN28: 0 | AO28: 0 | AP28: 0 | AQ28: 0 | AR28: 0 | AS28: 0 | AT28: 0 | AU28: 0 | AV28: 0 | AW28: 0 | AX28: 0 | AY28: 0 | AZ28: 0 | BA28: 0 | BB28: 0 | BC28: 0 | BD28: 0 | BE28: 0 | BF28: 0 | BG28: 0 | BH28: 0 | BI28: 0 | BJ28: 0 | BK28: 0 | BL28: 0 | BM28: 0 | BN28: 0
B29: New Leads per Day | D29: 10 | G29: =D29 -> 10 | H29: =G29 -> 10 | I29: =H29 -> 10 | J29: =I29 -> 10 | K29: =J29 -> 10 | L29: =K29 -> 10 | M29: =L29 -> 10 | N29: =M29 -> 10 | O29: =N29 -> 10 | ... BN29: =BM29 -> 10
B30: Conversion Rate | D30: 0.05 | G30: =D30 -> 0.05 | H30: =G30 -> 0.05 | I30: =H30 -> 0.05 | J30: =I30 -> 0.05 | K30: =J30 -> 0.05 | L30: =K30 -> 0.05 | M30: =L30 -> 0.05 | N30: =M30 -> 0.05 | O30: =N30 -> 0.05 | ... BN30: =BM30 -> 0.05
B31: New Customers | G31: =G28*G29*G30 -> 0.5 | H31: =H28*H29*H30 -> 0 | I31: =I28*I29*I30 -> 0 | J31: =J28*J29*J30 -> 0 | K31: =K28*K29*K30 -> 0 | L31: =L28*L29*L30 -> 0 | M31: =M28*M29*M30 -> 0 | N31: =N28*N29*N30 -> 0 | ... BN31: =BN28*BN29*BN30 -> 0
B33: Influencers
B34: Number of Influencers | D34: 2 | G34: =D34 -> 2 | H34: =G34 -> 2 | I34: =H34 -> 2 | J34: =I34 -> 2 | K34: =J34 -> 2 | L34: =K34 -> 2 | M34: =L34 -> 2 | N34: =M34 -> 2 | O34: =N34 -> 2 | ... BN34: =BM34 -> 2
B35: New Monthly Posts per Influencer | D35: 100 | G35: =D35 -> 100 | H35: =G35 -> 100 | I35: =H35 -> 100 | J35: =I35 -> 100 | K35: =J35 -> 100 | L35: =K35 -> 100 | M35: =L35 -> 100 | N35: =M35 -> 100 | O35: =N35 -> 100 | ... BN35: =BM35 -> 100
B36: New Monthly Leads per Post | D36: 5 | G36: =D36 -> 5 | H36: =G36 -> 5 | I36: =H36 -> 5 | J36: =I36 -> 5 | K36: =J36 -> 5 | L36: =K36 -> 5 | M36: =L36 -> 5 | N36: =M36 -> 5 | O36: =N36 -> 5 | ... BN36: =BM36 -> 5
B37: Conversion Rate | D37: 0.05 | G37: =D37 -> 0.05 | H37: =G37 -> 0.05 | I37: =H37 -> 0.05 | J37: =I37 -> 0.05 | K37: =J37 -> 0.05 | L37: =K37 -> 0.05 | M37: =L37 -> 0.05 | N37: =M37 -> 0.05 | O37: =N37 -> 0.05 | ... BN37: =BM37 -> 0.05
B38: New Customers | G38: =G34*G35*G36*G37 -> 50 | H38: =H34*H35*H36*H37 -> 50 | I38: =I34*I35*I36*I37 -> 50 | J38: =J34*J35*J36*J37 -> 50 | K38: =K34*K35*K36*K37 -> 50 | L38: =L34*L35*L36*L37 -> 50 | M38: =M34*M35*M36*M37 -> 50 | N38: =N34*N35*N36*N37 -> 50 | ... BN38: =BN34*BN35*BN36*BN37 -> 50
B40: Customer Referrals
B41: Previous Months New Customers | D41: =C71 | G41: =F71 | H41: =G71 -> 265.5 | I41: =H71 -> 273.9825 | J41: =I71 -> 274.10974 | K41: =J71 -> 274.11165 | L41: =K71 -> 274.11167 | M41: =L71 -> 274.11168 | N41: =M71 -> 274.11168 | ... BN41: =BM71 -> 274.11168
B42: Referral Percentage | D42: 0.3 | G42: =D42 -> 0.3 | H42: =G42 -> 0.3 | I42: =H42 -> 0.3 | J42: =I42 -> 0.3 | K42: =J42 -> 0.3 | L42: =K42 -> 0.3 | M42: =L42 -> 0.3 | N42: =M42 -> 0.3 | O42: =N42 -> 0.3 | ... BN42: =BM42 -> 0.3
B43: Conversion Rate | D43: 0.05 | G43: =D43 -> 0.05 | H43: =G43 -> 0.05 | I43: =H43 -> 0.05 | J43: =I43 -> 0.05 | K43: =J43 -> 0.05 | L43: =K43 -> 0.05 | M43: =L43 -> 0.05 | N43: =M43 -> 0.05 | O43: =N43 -> 0.05 | ... BN43: =BM43 -> 0.05
B44: New Customers | G44: =G41*G42*G43 -> 0 | H44: =H41*H42*H43 -> 3.9825 | I44: =I41*I42*I43 -> 4.1097375 | J44: =J41*J42*J43 -> 4.1116461 | K44: =K41*K42*K43 -> 4.1116747 | L44: =L41*L42*L43 -> 4.1116751 | M44: =M41*M42*M43 -> 4.1116751 | N44: =N41*N42*N43 -> 4.1116751 | ... BN44: =BN41*BN42*BN43 -> 4.1116751
B46: Partnerships
B47: Active Partnerships | D47: 2 | G47: =D47 -> 2 | H47: =G47 -> 2 | I47: =H47 -> 2 | J47: =I47 -> 2 | K47: =J47 -> 2 | L47: =K47 -> 2 | M47: =L47 -> 2 | N47: =M47 -> 2 | O47: =N47 -> 2 | ... BN47: =BM47 -> 2
B48: New Monthly Leads per Partnership | D48: 100 | G48: =D48 -> 100 | H48: =G48 -> 100 | I48: =H48 -> 100 | J48: =I48 -> 100 | K48: =J48 -> 100 | L48: =K48 -> 100 | M48: =L48 -> 100 | N48: =M48 -> 100 | O48: =N48 -> 100 | ... BN48: =BM48 -> 100
B49: Conversion Rate | D49: 0.05 | G49: =D49 -> 0.05 | H49: =G49 -> 0.05 | I49: =H49 -> 0.05 | J49: =I49 -> 0.05 | K49: =J49 -> 0.05 | L49: =K49 -> 0.05 | M49: =L49 -> 0.05 | N49: =M49 -> 0.05 | O49: =N49 -> 0.05 | ... BN49: =BM49 -> 0.05
...

Sheet Financials
B1: Year Counter | F1: 1 | G1: 1 | H1: 1 | I1: 1 | J1: 1 | K1: 1 | L1: 1 | M1: 1 | N1: 1 | O1: 1 | P1: 1 | Q1: 1 | R1: =F1+1 -> 2 | S1: =G1+1 -> 2 | T1: =H1+1 -> 2 | U1: =I1+1 -> 2 | V1: =J1+1 -> 2 | W1: =K1+1 -> 2 | X1: =L1+1 -> 2 | Y1: =M1+1 -> 2 | ... BM1: =BA1+1 -> 5
B2: Year | F2: =YEAR(F4) -> 2026 | G2: =YEAR(G4) -> 2026 | H2: =YEAR(H4) -> 2026 | I2: =YEAR(I4) -> 2026 | J2: =YEAR(J4) -> 2026 | K2: =YEAR(K4) -> 2026 | L2: =YEAR(L4) -> 2026 | M2: =YEAR(M4) -> 2026 | ... BM2: =YEAR(BM4) -> 2031
B3: Month Counter | F3: 1 | G3: =F3+1 -> 2 | H3: =G3+1 -> 3 | I3: =H3+1 -> 4 | J3: =I3+1 -> 5 | K3: =J3+1 -> 6 | L3: =K3+1 -> 7 | M3: =L3+1 -> 8 | N3: =M3+1 -> 9 | ... BM3: =BL3+1 -> 60
B4: Date | F4: =Assumptions!G4 -> 46081 | G4: =EOMONTH(F4,1) -> 46112 | H4: =EOMONTH(G4,1) -> 46142 | I4: =EOMONTH(H4,1) -> 46173 | J4: =EOMONTH(I4,1) -> 46203 | K4: =EOMONTH(J4,1) -> 46234 | L4: =EOMONTH(K4,1) -> 46265 | M4: =EOMONTH(L4,1) -> 46295 | N4: =EOMONTH(M4,1) -> 46326 | ... BM4: =EOMONTH(BL4,1) -> 47879
B6: Income Statement:
B8: Revenue | F8: =sum(F9:F11) -> 60268.5 | G8: =sum(G9:G11) -> 92328.277 | H8: =sum(H9:H11) -> 108387.05 | I8: =sum(I9:I11) -> 116416.87 | J8: =sum(J9:J11) -> 120431.78 | K8: =sum(K9:K11) -> 122439.24 | L8: =sum(L9:L11) -> 123442.97 | M8: =sum(M9:M11) -> 123944.84 | ... BM8: =sum(BM9:BM11) -> 124446.7
B9: =Assumptions!B75 -> Product Purchases #1 | F9: =Assumptions!G85 -> 19912.5 | G9: =Assumptions!H85 -> 30504.938 | H9: =Assumptions!I85 -> 35810.699 | I9: =Assumptions!J85 -> 38463.723 | J9: =Assumptions!K85 -> 39790.237 | K9: =Assumptions!L85 -> 40453.494 | L9: =Assumptions!M85 -> 40785.123 | M9: =Assumptions!N85 -> 40950.937 | ... BN9: =Assumptions!BO85
B10: =Assumptions!B87 -> Product Purchases #2 | F10: =Assumptions!G97 -> 39825 | G10: =Assumptions!H97 -> 61009.875 | H10: =Assumptions!I97 -> 71621.398 | I10: =Assumptions!J97 -> 76927.446 | J10: =Assumptions!K97 -> 79580.474 | K10: =Assumptions!L97 -> 80906.988 | L10: =Assumptions!M97 -> 81570.245 | M10: =Assumptions!N97 -> 81901.874 | ... BN10: =Assumptions!BO97
B11: =Assumptions!B99 -> Monthly Subscription Purchases | F11: =Assumptions!G108 -> 531 | G11: =Assumptions!H108 -> 813.465 | H11: =Assumptions!I108 -> 954.95197 | I11: =Assumptions!J108 -> 1025.6993 | J11: =Assumptions!K108 -> 1061.073 | K11: =Assumptions!L108 -> 1078.7598 | L11: =Assumptions!M108 -> 1087.6033 | M11: =Assumptions!N108 -> 1092.025 | ... BM11: =Assumptions!BN108 -> 1096.4467
B13: COGS | F13: =Assumptions!G153 -> 24107.4 | G13: =Assumptions!H153 -> 36931.311 | H13: =Assumptions!I153 -> 43354.82 | I13: =Assumptions!J153 -> 46566.747 | J13: =Assumptions!K153 -> 48172.714 | K13: =Assumptions!L153 -> 48975.697 | L13: =Assumptions!M153 -> 49377.189 | M13: =Assumptions!N153 -> 49577.934 | ... BM13: =Assumptions!BN153 -> 49778.68
B15: Gross Profit | F15: =F8-F13 -> 36161.1 | G15: =G8-G13 -> 55396.967 | H15: =H8-H13 -> 65032.23 | I15: =I8-I13 -> 69850.121 | J15: =J8-J13 -> 72259.071 | K15: =K8-K13 -> 73463.545 | L15: =L8-L13 -> 74065.783 | M15: =M8-M13 -> 74366.902 | ... BM15: =BM8-BM13 -> 74668.02
B16: Gross Margin | F16: =F15/F8 -> 0.6 | G16: =G15/G8 -> 0.6 | H16: =H15/H8 -> 0.6 | I16: =I15/I8 -> 0.6 | J16: =J15/J8 -> 0.6 | K16: =K15/K8 -> 0.6 | L16: =L15/L8 -> 0.6 | M16: =M15/M8 -> 0.6 | ... BM16: =BM15/BM8 -> 0.6
B18: Operating Expenses
B19: Salaries & Benefits | F19: =SUM(Assumptions!G116:G140) -> 202000 | G19: =SUM(Assumptions!H116:H140) -> 202000 | H19: =SUM(Assumptions!I116:I140) -> 202000 | I19: =SUM(Assumptions!J116:J140) -> 202000 | J19: =SUM(Assumptions!K116:K140) -> 202000 | K19: =SUM(Assumptions!L116:L140) -> 202000 | L19: =SUM(Assumptions!M116:M140) -> 202000 | M19: =SUM(Assumptions!N116:N140) -> 202000 | ... BM19: =SUM(Assumptions!BN116:BN140) -> 202000
B20: =Assumptions!B155 -> General & Admin | F20: =sum(Assumptions!G156:G163) -> 20000 | G20: =sum(Assumptions!H156:H163) -> 20000 | H20: =sum(Assumptions!I156:I163) -> 20000 | I20: =sum(Assumptions!J156:J163) -> 20000 | J20: =sum(Assumptions!K156:K163) -> 20000 | K20: =sum(Assumptions!L156:L163) -> 20000 | L20: =sum(Assumptions!M156:M163) -> 20000 | M20: =sum(Assumptions!N156:N163) -> 20000 | ... BM20: =sum(Assumptions!BN156:BN163) -> 20000
B21: =Assumptions!B166 -> Sales & Marketing | F21: =sum(Assumptions!G167:G168) -> 14821.48 | G21: =sum(Assumptions!H167:H168) -> 17386.262 | H21: =sum(Assumptions!I167:I168) -> 18670.964 | I21: =sum(Assumptions!J167:J168) -> 19313.349 | J21: =sum(Assumptions!K167:K168) -> 19634.543 | K21: =sum(Assumptions!L167:L168) -> 19795.139 | L21: =sum(Assumptions!M167:M168) -> 19875.438 | M21: =sum(Assumptions!N167:N168) -> 19915.587 | ... BM21: =sum(Assumptions!BN167:BN168) -> 19955.736
B22: =Assumptions!B171 -> Professional Fees | F22: =SUM(Assumptions!G172:G174) -> 5000 | G22: =SUM(Assumptions!H172:H174) -> 5000 | H22: =SUM(Assumptions!I172:I174) -> 5000 | I22: =SUM(Assumptions!J172:J174) -> 5000 | J22: =SUM(Assumptions!K172:K174) -> 5000 | K22: =SUM(Assumptions!L172:L174) -> 5000 | L22: =SUM(Assumptions!M172:M174) -> 5000 | M22: =SUM(Assumptions!N172:N174) -> 5000 | ... BM22: =SUM(Assumptions!BN172:BN174) -> 5000
B23: =Assumptions!B177 -> Other | F23: =Assumptions!G178 -> 6026.85 | G23: =Assumptions!H178 -> 9232.8278 | H23: =Assumptions!I178 -> 10838.705 | I23: =Assumptions!J178 -> 11641.687 | J23: =Assumptions!K178 -> 12043.178 | K23: =Assumptions!L178 -> 12243.924 | L23: =Assumptions!M178 -> 12344.297 | M23: =Assumptions!N178 -> 12394.484 | ... BM23: =Assumptions!BN178 -> 12444.67
B24: Total Operating Expenses | F24: =SUM(F19:F23) -> 247848.33 | G24: =SUM(G19:G23) -> 253619.09 | H24: =SUM(H19:H23) -> 256509.67 | I24: =SUM(I19:I23) -> 257955.04 | J24: =SUM(J19:J23) -> 258677.72 | K24: =SUM(K19:K23) -> 259039.06 | L24: =SUM(L19:L23) -> 259219.73 | M24: =SUM(M19:M23) -> 259310.07 | ... BM24: =SUM(BM19:BM23) -> 259400.41
B26: EBITDA | F26: =F15-F24 -> -211687.23 | G26: =G15-G24 -> -198222.12 | H26: =H15-H24 -> -191477.44 | I26: =I15-I24 -> -188104.92 | J26: =J15-J24 -> -186418.65 | K26: =K15-K24 -> -185575.52 | L26: =L15-L24 -> -185153.95 | M26: =M15-M24 -> -184943.17 | ... BM26: =BM15-BM24 -> -184732.39
B27: Depreciation | F27: =SUM(Assumptions!G201:G204)-sum(Assumptions!E201:E204) -> 0 | G27: =SUM(Assumptions!H201:H204)-sum(Assumptions!G201:G204) -> 0 | H27: =SUM(Assumptions!I201:I204)-sum(Assumptions!H201:H204) -> 0 | I27: =SUM(Assumptions!J201:J204)-sum(Assumptions!I201:I204) -> 0 | J27: =SUM(Assumptions!K201:K204)-sum(Assumptions!J201:J204) -> 0 | K27: =SUM(Assumptions!L201:L204)-sum(Assumptions!K201:K204) -> 0 | L27: =SUM(Assumptions!M201:M204)-sum(Assumptions!L201:L204) -> 0 | M27: =SUM(Assumptions!N201:N204)-sum(Assumptions!M201:M204) -> 0 | N27: =SUM(Assumptions!O201:O204)-sum(Assumptions!N201:N204) -> 0 | ... BM27: =SUM(Assumptions!BN201:BN204)-sum(Assumptions!BM201:BM204) -> 0
B28: EBIT | F28: =F26-F27 -> -211687.23 | G28: =G26-G27 -> -198222.12 | H28: =H26-H27 -> -191477.44 | I28: =I26-I27 -> -188104.92 | J28: =J26-J27 -> -186418.65 | K28: =K26-K27 -> -185575.52 | L28: =L26-L27 -> -185153.95 | M28: =M26-M27 -> -184943.17 | ... BM28: =BM26-BM27 -> -184732.39
B29: Taxes | F29: =IF(F28>0,F28*Assumptions!$C$180,0) -> 0 | G29: =IF(G28>0,G28*Assumptions!$C$180,0) -> 0 | H29: =IF(H28>0,H28*Assumptions!$C$180,0) -> 0 | I29: =IF(I28>0,I28*Assumptions!$C$180,0) -> 0 | J29: =IF(J28>0,J28*Assumptions!$C$180,0) -> 0 | K29: =IF(K28>0,K28*Assumptions!$C$180,0) -> 0 | L29: =IF(L28>0,L28*Assumptions!$C$180,0) -> 0 | M29: =IF(M28>0,M28*Assumptions!$C$180,0) -> 0 | ... BM29: =IF(BM28>0,BM28*Assumptions!$C$180,0) -> 0
B30: Net Income | F30: =F28-F29 -> -211687.23 | G30: =G28-G29 -> -198222.12 | H30: =H28-H29 -> -191477.44 | I30: =I28-I29 -> -188104.92 | J30: =J28-J29 -> -186418.65 | K30: =K28-K29 -> -185575.52 | L30: =L28-L29 -> -185153.95 | M30: =M28-M29 -> -184943.17 | ... BM30: =BM28-BM29 -> -184732.39
B31: Net Margin | F31: =F30/F8 -> -3.5124025 | G31: =G30/G8 -> -2.1469276 | H31: =H30/H8 -> -1.7666081 | I31: =I30/I8 -> -1.6157875 | J31: =J30/J8 -> -1.547919 | K31: =K30/K8 -> -1.5156539 | L31: =L30/L8 -> -1.4999149 | M31: =M30/M8 -> -1.492141 | ... BM31: =BM30/BM8 -> -1.4844298
B33: Balance Sheet:
B35: Assets
B36: Current Assets
B37: Cash | F37: =F82 -> 269048.98 | G37: =G82 -> 51270.397 | H37: =H82 -> -150002.89 | I37: =I82 -> -343006 | J37: =J82 -> -531873.75 | K37: =K82 -> -718673.81 | L37: =L82 -> -904440.04 | M37: =M82 -> -1089689.3 | ... BM37: =BM82 -> -10696290
B38: Accounts Receivable | F38: =Assumptions!G190 -> 30134.25 | G38: =Assumptions!H190 -> 46164.139 | H38: =Assumptions!I190 -> 54193.525 | I38: =Assumptions!J190 -> 58208.434 | J38: =Assumptions!K190 -> 60215.892 | K38: =Assumptions!L190 -> 61219.621 | L38: =Assumptions!M190 -> 61721.486 | M38: =Assumptions!N190 -> 61972.418 | ... BM38: =Assumptions!BN190 -> 62223.35
B39: Inventory | F39: =Assumptions!G192 -> 24107.4 | G39: =Assumptions!H192 -> 36931.311 | H39: =Assumptions!I192 -> 43354.82 | I39: =Assumptions!J192 -> 46566.747 | J39: =Assumptions!K192 -> 48172.714 | K39: =Assumptions!L192 -> 48975.697 | L39: =Assumptions!M192 -> 49377.189 | M39: =Assumptions!N192 -> 49577.934 | ... BN39: =Assumptions!BO192
B40: Total Current Assets | F40: =SUM(F37:F39) -> 323290.64 | G40: =SUM(G37:G39) -> 134365.85 | H40: =SUM(H37:H39) -> -52454.549 | I40: =SUM(I37:I39) -> -238230.82 | J40: =SUM(J37:J39) -> -423485.14 | K40: =SUM(K37:K39) -> -608478.5 | L40: =SUM(L37:L39) -> -793341.37 | M40: =SUM(M37:M39) -> -978139 | ... BM40: =SUM(BM37:BM39) -> -10584288
B42: Fixed Assets | F42: =SUM(Assumptions!G194:G198) -> 0 | G42: =SUM(Assumptions!H194:H198) -> 0 | H42: =SUM(Assumptions!I194:I198) -> 0 | I42: =SUM(Assumptions!J194:J198) -> 0 | J42: =SUM(Assumptions!K194:K198) -> 0 | K42: =SUM(Assumptions!L194:L198) -> 0 | L42: =SUM(Assumptions!M194:M198) -> 0 | M42: =SUM(Assumptions!N194:N198) -> 0 | ... BM42: =SUM(Assumptions!BN194:BN198) -> 0
B43: Accumulated Depreciation | F43: =-SUM(Assumptions!G201:G204) -> 0 | G43: =-SUM(Assumptions!H201:H204) -> 0 | H43: =-SUM(Assumptions!I201:I204) -> 0 | I43: =-SUM(Assumptions!J201:J204) -> 0 | J43: =-SUM(Assumptions!K201:K204) -> 0 | K43: =-SUM(Assumptions!L201:L204) -> 0 | L43: =-SUM(Assumptions!M201:M204) -> 0 | M43: =-SUM(Assumptions!N201:N204) -> 0 | ... BM43: =-SUM(Assumptions!BN201:BN204) -> 0
B44: Total Assets | F44: =SUM(F40:F43) -> 323290.64 | G44: =SUM(G40:G43) -> 134365.85 | H44: =SUM(H40:H43) -> -52454.549 | I44: =SUM(I40:I43) -> -238230.82 | J44: =SUM(J40:J43) -> -423485.14 | K44: =SUM(K40:K43) -> -608478.5 | L44: =SUM(L40:L43) -> -793341.37 | M44: =SUM(M40:M43) -> -978139 | ... BM44: =SUM(BM40:BM43) -> -10584288
B46: Liabilities & Owner's Equity
B47: Liabilities
B48: Accounts payable | F48: =Assumptions!G208 -> 34977.865 | G48: =Assumptions!H208 -> 44275.2 | H48: =Assumptions!I208 -> 48932.244 | I48: =Assumptions!J208 -> 51260.892 | J48: =Assumptions!K208 -> 52425.217 | K48: =Assumptions!L208 -> 53007.38 | L48: =Assumptions!M208 -> 53298.462 | M48: =Assumptions!N208 -> 53444.002 | ... BM48: =Assumptions!BN208 -> 53589.543
B49: Total Liabilities | F49: =F48 -> 34977.865 | G49: =G48 -> 44275.2 | H49: =H48 -> 48932.244 | I49: =I48 -> 51260.892 | J49: =J48 -> 52425.217 | K49: =K48 -> 53007.38 | L49: =L48 -> 53298.462 | M49: =M48 -> 53444.002 | ... BM49: =BM48 -> 53589.543
B51: Equity | E51: Prev Cash
...
