Workbook

Sheet Overview
C2: YOUR LOGO HERE
C4: Financial Model
G5: Welcome! This template was created by Forecastr's team of Financial Analysts and Fractional CFOs to help our fellow founders create better financial models for their startups and small businesses. Forecastr is an out-of-the-box finance function for your business. We provide the tools and support you need to create an investor-grade financial model. Our analysts work with you every step of the way to build a model that's customized to fit your business, keep it up to date, and generate insightful reports to share with your investors and other stakeholders. ✔ Impress your investors ✔ Hit your growth targets ✔ Never run out of cash
C7: Your Website Link Here
C10: Table of Contents
C12: Assumptions
C14: Financials
I18: SCHEDULE A MODELING SESSION WITH A MEMBER OF OUR TEAM

Sheet Assumptions
B1: Year Counter | R1: 1 | S1: 1 | T1: 1 | U1: 1 | V1: 1 | W1: 1 | X1: 1 | Y1: 1 | Z1: 1 | AA1: 1 | AB1: 1 | AC1: 1 | AD1: =R1+1 -> 2 | AE1: =S1+1 -> 2 | AF1: =T1+1 -> 2 | AG1: =U1+1 -> 2 | AH1: =V1+1 -> 2 | AI1: =W1+1 -> 2 | AJ1: =X1+1 -> 2 | AK1: =Y1+1 -> 2 | ... BY1: =BM1+1 -> 5
B2: Year | R2: =YEAR(R4) -> 2023 | S2: =YEAR(S4) -> 2023 | T2: =YEAR(T4) -> 2023 | U2: =YEAR(U4) -> 2023 | V2: =YEAR(V4) -> 2023 | W2: =YEAR(W4) -> 2023 | X2: =YEAR(X4) -> 2023 | Y2: =YEAR(Y4) -> 2023 | ... BY2: =YEAR(BY4) -> 2027
B3: Month Counter | R3: 1 | S3: =R3+1 -> 2 | T3: =S3+1 -> 3 | U3: =T3+1 -> 4 | V3: =U3+1 -> 5 | W3: =V3+1 -> 6 | X3: =W3+1 -> 7 | Y3: =X3+1 -> 8 | Z3: =Y3+1 -> 9 | ... BY3: =BX3+1 -> 60
B4: Date | R4: 44957 | S4: =EOMONTH(R4,1) -> 44985 | T4: =EOMONTH(S4,1) -> 45016 | U4: =EOMONTH(T4,1) -> 45046 | V4: =EOMONTH(U4,1) -> 45077 | W4: =EOMONTH(V4,1) -> 45107 | X4: =EOMONTH(W4,1) -> 45138 | Y4: =EOMONTH(X4,1) -> 45169 | Z4: =EOMONTH(Y4,1) -> 45199 | ... BY4: =EOMONTH(BX4,1) -> 46752
B6: Customer Acquisition:
B8: Build Customer Acquisition Channels
B10: Organic / Word of Mouth
B11: Web Traffic | D11: 5000 | R11: =D11 -> 5000 | S11: =R11 -> 5000 | T11: =S11 -> 5000 | U11: =T11 -> 5000 | V11: =U11 -> 5000 | W11: =V11 -> 5000 | X11: =W11 -> 5000 | Y11: =X11 -> 5000 | Z11: =Y11 -> 5000 | ... BY11: =BX11 -> 5000
B12: Conversion Rate | D12: 0.02 | R12: =D12 -> 0.02 | S12: =R12 -> 0.02 | T12: =S12 -> 0.02 | U12: =T12 -> 0.02 | V12: =U12 -> 0.02 | W12: =V12 -> 0.02 | X12: =W12 -> 0.02 | Y12: =X12 -> 0.02 | Z12: =Y12 -> 0.02 | ... BY12: =BX12 -> 0.02
B13: New Customers | R13: =R11*R12 -> 100 | S13: =S11*S12 -> 100 | T13: =T11*T12 -> 100 | U13: =U11*U12 -> 100 | V13: =V11*V12 -> 100 | W13: =W11*W12 -> 100 | X13: =X11*X12 -> 100 | Y13: =Y11*Y12 -> 100 | ... BY13: =BY11*BY12 -> 100
B15: Paid Advertising
B16: Budget per Month | D16: 5000 | R16: =D16 -> 5000 | S16: =R16 -> 5000 | T16: =S16 -> 5000 | U16: =T16 -> 5000 | V16: =U16 -> 5000 | W16: =V16 -> 5000 | X16: =W16 -> 5000 | Y16: =X16 -> 5000 | Z16: =Y16 -> 5000 | ... BY16: =BX16 -> 5000
B17: Average CPC | D17: 2 | R17: =D17 -> 2 | S17: =R17 -> 2 | T17: =S17 -> 2 | U17: =T17 -> 2 | V17: =U17 -> 2 | W17: =V17 -> 2 | X17: =W17 -> 2 | Y17: =X17 -> 2 | Z17: =Y17 -> 2 | ... BY17: =BX17 -> 2
B18: Conversion Rate | D18: 0.05 | R18: =D18 -> 0.05 | S18: =R18 -> 0.05 | T18: =S18 -> 0.05 | U18: =T18 -> 0.05 | V18: =U18 -> 0.05 | W18: =V18 -> 0.05 | X18: =W18 -> 0.05 | Y18: =X18 -> 0.05 | Z18: =Y18 -> 0.05 | ... BY18: =BX18 -> 0.05
B19: New Customers | R19: =(D16/D17)*D18 -> 125 | S19: =(S16/S17)*S18 -> 125 | T19: =(T16/T17)*T18 -> 125 | U19: =(U16/U17)*U18 -> 125 | V19: =(V16/V17)*V18 -> 125 | W19: =(W16/W17)*W18 -> 125 | X19: =(X16/X17)*X18 -> 125 | Y19: =(Y16/Y17)*Y18 -> 125 | Z19: =(Z16/Z17)*Z18 -> 125 | ... BY19: =(BY16/BY17)*BY18 -> 125
B21: Affiliates
B22: Number of Affiliates | D22: 5 | R22: =D22 -> 5 | S22: =R22 -> 5 | T22: =S22 -> 5 | U22: =T22 -> 5 | V22: =U22 -> 5 | W22: =V22 -> 5 | X22: =W22 -> 5 | Y22: =X22 -> 5 | Z22: =Y22 -> 5 | ... BY22: =BX22 -> 5
B23: New Monthly Leads per Affiliate | D23: 50 | R23: =D23 -> 50 | S23: =R23 -> 50 | T23: =S23 -> 50 | U23: =T23 -> 50 | V23: =U23 -> 50 | W23: =V23 -> 50 | X23: =W23 -> 50 | Y23: =X23 -> 50 | Z23: =Y23 -> 50 | ... BY23: =BX23 -> 50
B24: Conversion Rate | D24: 0.05 | R24: =D24 -> 0.05 | S24: =R24 -> 0.05 | T24: =S24 -> 0.05 | U24: =T24 -> 0.05 | V24: =U24 -> 0.05 | W24: =V24 -> 0.05 | X24: =W24 -> 0.05 | Y24: =X24 -> 0.05 | Z24: =Y24 -> 0.05 | ... BY24: =BX24 -> 0.05
B25: New Customers | R25: =R22*R23*R24 -> 12.5 | S25: =S22*S23*S24 -> 12.5 | T25: =T22*T23*T24 -> 12.5 | U25: =U22*U23*U24 -> 12.5 | V25: =V22*V23*V24 -> 12.5 | W25: =W22*W23*W24 -> 12.5 | X25: =X22*X23*X24 -> 12.5 | Y25: =Y22*Y23*Y24 -> 12.5 | ... BY25: =BY22*BY23*BY24 -> 12.5
B27: Conferences
B28: Conferences Atteneded | R28: 1 | S28: 0 | T28: 0 | U28: 0 | V28: 0 | W28: 0 | X28: 0 | Y28: 0 | Z28: 0 | AA28: 0 | AB28: 0 | AC28: 0 | AD28: 0 | AE28: 0 | AF28: 0 | AG28: 0 | AH28: 0 | AI28: 0 | AJ28: 0 | AK28: 0 | AL28: 0 | AM28: 0 | AN28: 0 | AO28: 0 | AP28: 0 | AQ28: 0 | AR28: 0 | AS28: 0 | AT28: 0 | AU28: 0 | AV28: 0 | AW28: 0 | AX28: 0 | AY28: 0 | AZ28: 0 | BA28: 0 | BB28: 0 | BC28: 0 | BD28: 0 | BE28: 0 | BF28: 0 | BG28: 0 | BH28: 0 | BI28: 0 | BJ28: 0 | BK28: 0 | BL28: 0 | BM28: 0 | BN28: 0 | BO28: 0 | BP28: 0 | BQ28: 0 | BR28: 0 | BS28: 0 | BT28: 0 | BU28: 0 | BV28: 0 | BW28: 0 | BX28: 0 | BY28: 0
B29: New Leads per Conference | D29: 50 | R29: =D29 -> 50 | S29: =R29 -> 50 | T29: =S29 -> 50 | U29: =T29 -> 50 | V29: =U29 -> 50 | W29: =V29 -> 50 | X29: =W29 -> 50 | Y29: =X29 -> 50 | Z29: =Y29 -> 50 | ... BY29: =BX29 -> 50
B30: Conversion Rate | D30: 0.05 | R30: =D30 -> 0.05 | S30: =R30 -> 0.05 | T30: =S30 -> 0.05 | U30: =T30 -> 0.05 | V30: =U30 -> 0.05 | W30: =V30 -> 0.05 | X30: =W30 -> 0.05 | Y30: =X30 -> 0.05 | Z30: =Y30 -> 0.05 | ... BY30: =BX30 -> 0.05
B31: New Customers | R31: =R28*R29*R30 -> 2.5 | S31: =S28*S29*S30 -> 0 | T31: =T28*T29*T30 -> 0 | U31: =U28*U29*U30 -> 0 | V31: =V28*V29*V30 -> 0 | W31: =W28*W29*W30 -> 0 | X31: =X28*X29*X30 -> 0 | Y31: =Y28*Y29*Y30 -> 0 | ... BY31: =BY28*BY29*BY30 -> 0
B33: Influencers
B34: Number of Influencers | D34: 2 | R34: =D34 -> 2 | S34: =R34 -> 2 | T34: =S34 -> 2 | U34: =T34 -> 2 | V34: =U34 -> 2 | W34: =V34 -> 2 | X34: =W34 -> 2 | Y34: =X34 -> 2 | Z34: =Y34 -> 2 | ... BY34: =BX34 -> 2
B35: New Monthly Posts per Influencer | D35: 100 | R35: =D35 -> 100 | S35: =R35 -> 100 | T35: =S35 -> 100 | U35: =T35 -> 100 | V35: =U35 -> 100 | W35: =V35 -> 100 | X35: =W35 -> 100 | Y35: =X35 -> 100 | Z35: =Y35 -> 100 | ... BY35: =BX35 -> 100
B36: New Monthly Leads per Post | D36: 5 | R36: =D36 -> 5 | S36: =R36 -> 5 | T36: =S36 -> 5 | U36: =T36 -> 5 | V36: =U36 -> 5 | W36: =V36 -> 5 | X36: =W36 -> 5 | Y36: =X36 -> 5 | Z36: =Y36 -> 5 | ... BY36: =BX36 -> 5
B37: Conversion Rate | D37: 0.05 | R37: =D37 -> 0.05 | S37: =R37 -> 0.05 | T37: =S37 -> 0.05 | U37: =T37 -> 0.05 | V37: =U37 -> 0.05 | W37: =V37 -> 0.05 | X37: =W37 -> 0.05 | Y37: =X37 -> 0.05 | Z37: =Y37 -> 0.05 | ... BY37: =BX37 -> 0.05
B38: New Customers | R38: =R34*R35*R36*R37 -> 50 | S38: =S34*S35*S36*S37 -> 50 | T38: =T34*T35*T36*T37 -> 50 | U38: =U34*U35*U36*U37 -> 50 | V38: =V34*V35*V36*V37 -> 50 | W38: =W34*W35*W36*W37 -> 50 | X38: =X34*X35*X36*X37 -> 50 | Y38: =Y34*Y35*Y36*Y37 -> 50 | ... BY38: =BY34*BY35*BY36*BY37 -> 50
B40: Customer Referrals
B41: Previous Months New Customers | R41: =Q71 | S41: =R71 -> 317.5 | T41: =S71 -> 324.7625 | U41: =T71 -> 324.87144 | V41: =U71 -> 324.87307 | W41: =V71 -> 324.8731 | X41: =W71 -> 324.8731 | Y41: =X71 -> 324.8731 | ... BY41: =BX71 -> 324.8731
B42: Referral Percentage | D42: 0.3 | R42: =D42 -> 0.3 | S42: =R42 -> 0.3 | T42: =S42 -> 0.3 | U42: =T42 -> 0.3 | V42: =U42 -> 0.3 | W42: =V42 -> 0.3 | X42: =W42 -> 0.3 | Y42: =X42 -> 0.3 | Z42: =Y42 -> 0.3 | ... BY42: =BX42 -> 0.3
B43: Conversion Rate | D43: 0.05 | R43: =D43 -> 0.05 | S43: =R43 -> 0.05 | T43: =S43 -> 0.05 | U43: =T43 -> 0.05 | V43: =U43 -> 0.05 | W43: =V43 -> 0.05 | X43: =W43 -> 0.05 | Y43: =X43 -> 0.05 | Z43: =Y43 -> 0.05 | ... BY43: =BX43 -> 0.05
B44: New Customers | R44: =R41*R42*R43 -> 0 | S44: =S41*S42*S43 -> 4.7625 | T44: =T41*T42*T43 -> 4.8714375 | U44: =U41*U42*U43 -> 4.8730716 | V44: =V41*V42*V43 -> 4.8730961 | W44: =W41*W42*W43 -> 4.8730964 | X44: =X41*X42*X43 -> 4.8730964 | Y44: =Y41*Y42*Y43 -> 4.8730964 | ... BY44: =BY41*BY42*BY43 -> 4.8730964
B46: Partnerships
B47: Active Partnerships | D47: 2 | R47: =D47 -> 2 | S47: =R47 -> 2 | T47: =S47 -> 2 | U47: =T47 -> 2 | V47: =U47 -> 2 | W47: =V47 -> 2 | X47: =W47 -> 2 | Y47: =X47 -> 2 | Z47: =Y47 -> 2 | ... BY47: =BX47 -> 2
B48: New Monthly Leads per Partnership | D48: 100 | R48: =D48 -> 100 | S48: =R48 -> 100 | T48: =S48 -> 100 | U48: =T48 -> 100 | V48: =U48 -> 100 | W48: =V48 -> 100 | X48: =W48 -> 100 | Y48: =X48 -> 100 | Z48: =Y48 -> 100 | ... BY48: =BX48 -> 100
B49: Conversion Rate | D49: 0.05 | R49: =D49 -> 0.05 | S49: =R49 -> 0.05 | T49: =S49 -> 0.05 | U49: =T49 -> 0.05 | V49: =U49 -> 0.05 | W49: =V49 -> 0.05 | X49: =W49 -> 0.05 | Y49: =X49 -> 0.05 | Z49: =Y49 -> 0.05 | ... BY49: =BX49 -> 0.05
...

Sheet Financials
B1: Year Counter | F1: 1 | G1: 1 | H1: 1 | I1: 1 | J1: 1 | K1: 1 | L1: 1 | M1: 1 | N1: 1 | O1: 1 | P1: 1 | Q1: 1 | R1: =F1+1 -> 2 | S1: =G1+1 -> 2 | T1: =H1+1 -> 2 | U1: =I1+1 -> 2 | V1: =J1+1 -> 2 | W1: =K1+1 -> 2 | X1: =L1+1 -> 2 | Y1: =M1+1 -> 2 | ... BM1: =BA1+1 -> 5
B2: Year | F2: =YEAR(F4) -> 2023 | G2: =YEAR(G4) -> 2023 | H2: =YEAR(H4) -> 2023 | I2: =YEAR(I4) -> 2023 | J2: =YEAR(J4) -> 2023 | K2: =YEAR(K4) -> 2023 | L2: =YEAR(L4) -> 2023 | M2: =YEAR(M4) -> 2023 | ... BM2: =YEAR(BM4) -> 2027
B3: Month Counter | F3: 1 | G3: =F3+1 -> 2 | H3: =G3+1 -> 3 | I3: =H3+1 -> 4 | J3: =I3+1 -> 5 | K3: =J3+1 -> 6 | L3: =K3+1 -> 7 | M3: =L3+1 -> 8 | N3: =M3+1 -> 9 | ... BM3: =BL3+1 -> 60
B4: Date | F4: =Assumptions!R4 -> 44957 | G4: =EOMONTH(F4,1) -> 44985 | H4: =EOMONTH(G4,1) -> 45016 | I4: =EOMONTH(H4,1) -> 45046 | J4: =EOMONTH(I4,1) -> 45077 | K4: =EOMONTH(J4,1) -> 45107 | L4: =EOMONTH(K4,1) -> 45138 | M4: =EOMONTH(L4,1) -> 45169 | N4: =EOMONTH(M4,1) -> 45199 | ... BM4: =EOMONTH(BL4,1) -> 46752
B6: Income Statement:
B8: Revenue | F8: =sum(F9:F11) -> 4762.5 | G8: =sum(G9:G11) -> 9633.9375 | H8: =sum(H9:H11) -> 14507.009 | I8: =sum(I9:I11) -> 19380.105 | J8: =sum(J9:J11) -> 24253.202 | K8: =sum(K9:K11) -> 29126.298 | L8: =sum(L9:L11) -> 33999.394 | M8: =sum(M9:M11) -> 38872.491 | ... BM8: =sum(BM9:BM11) -> 196530.82
B9: =Assumptions!B75 -> Annual SaaS Tier 1 | F9: =Assumptions!R88 -> 1322.9167 | G9: =Assumptions!S88 -> 2676.0938 | H9: =Assumptions!T88 -> 4029.7247 | I9: =Assumptions!U88 -> 5383.3625 | J9: =Assumptions!V88 -> 6737.0004 | K9: =Assumptions!W88 -> 8090.6383 | L9: =Assumptions!X88 -> 9444.2762 | M9: =Assumptions!Y88 -> 10797.914 | ... BN9: =Assumptions!BZ88
B10: =Assumptions!B90 -> Annual SaaS Tier 2 | F10: =Assumptions!R103 -> 1587.5 | G10: =Assumptions!S103 -> 3211.3125 | H10: =Assumptions!T103 -> 4835.6697 | I10: =Assumptions!U103 -> 6460.035 | J10: =Assumptions!V103 -> 8084.4005 | K10: =Assumptions!W103 -> 9708.766 | L10: =Assumptions!X103 -> 11333.131 | M10: =Assumptions!Y103 -> 12957.497 | ... BN10: =Assumptions!BZ103
B11: =Assumptions!B105 -> Annual SaaS Tier 3 | F11: =Assumptions!R118 -> 1852.0833 | G11: =Assumptions!S118 -> 3746.5312 | H11: =Assumptions!T118 -> 5641.6146 | I11: =Assumptions!U118 -> 7536.7076 | J11: =Assumptions!V118 -> 9431.8006 | K11: =Assumptions!W118 -> 11326.894 | L11: =Assumptions!X118 -> 13221.987 | M11: =Assumptions!Y118 -> 15117.08 | ... BN11: =Assumptions!BZ118
B13: COGS | F13: =Assumptions!R163 -> 1666.875 | G13: =Assumptions!S163 -> 3371.8781 | H13: =Assumptions!T163 -> 5077.4532 | I13: =Assumptions!U163 -> 6783.0368 | J13: =Assumptions!V163 -> 8488.6206 | K13: =Assumptions!W163 -> 10194.204 | L13: =Assumptions!X163 -> 11899.788 | M13: =Assumptions!Y163 -> 13605.372 | ... BM13: =Assumptions!BY163 -> 68785.788
B15: Gross Profit | F15: =F8-F13 -> 3095.625 | G15: =G8-G13 -> 6262.0594 | H15: =H8-H13 -> 9429.5559 | I15: =I8-I13 -> 12597.068 | J15: =J8-J13 -> 15764.581 | K15: =K8-K13 -> 18932.094 | L15: =L8-L13 -> 22099.606 | M15: =M8-M13 -> 25267.119 | ... BM15: =BM8-BM13 -> 127745.03
B16: Gross Margin | F16: =F15/F8 -> 0.65 | G16: =G15/G8 -> 0.65 | H16: =H15/H8 -> 0.65 | I16: =I15/I8 -> 0.65 | J16: =J15/J8 -> 0.65 | K16: =K15/K8 -> 0.65 | L16: =L15/L8 -> 0.65 | M16: =M15/M8 -> 0.65 | ... BM16: =BM15/BM8 -> 0.65
B18: Operating Expenses
B19: Salaries & Benefits | F19: =SUM(Assumptions!R126:R150) -> 202000 | G19: =SUM(Assumptions!S126:S150) -> 202000 | H19: =SUM(Assumptions!T126:T150) -> 202000 | I19: =SUM(Assumptions!U126:U150) -> 202000 | J19: =SUM(Assumptions!V126:V150) -> 202000 | K19: =SUM(Assumptions!W126:W150) -> 202000 | L19: =SUM(Assumptions!X126:X150) -> 202000 | M19: =SUM(Assumptions!Y126:Y150) -> 202000 | ... BM19: =SUM(Assumptions!BY126:BY150) -> 202000
B20: =Assumptions!B165 -> General & Admin | F20: =sum(Assumptions!R166:R173) -> 20000 | G20: =sum(Assumptions!S166:S173) -> 20000 | H20: =sum(Assumptions!T166:T173) -> 20000 | I20: =sum(Assumptions!U166:U173) -> 20000 | J20: =sum(Assumptions!V166:V173) -> 20000 | K20: =sum(Assumptions!W166:W173) -> 20000 | L20: =sum(Assumptions!X166:X173) -> 20000 | M20: =sum(Assumptions!Y166:Y173) -> 20000 | ... BM20: =sum(Assumptions!BY166:BY173) -> 20000
B21: =Assumptions!B176 -> Sales & Marketing | F21: =sum(Assumptions!R177:R178) -> 10381 | G21: =sum(Assumptions!S177:S178) -> 10770.715 | H21: =sum(Assumptions!T177:T178) -> 11160.561 | I21: =sum(Assumptions!U177:U178) -> 11550.408 | J21: =sum(Assumptions!V177:V178) -> 11940.256 | K21: =sum(Assumptions!W177:W178) -> 12330.104 | L21: =sum(Assumptions!X177:X178) -> 12719.952 | M21: =sum(Assumptions!Y177:Y178) -> 13109.799 | ... BM21: =sum(Assumptions!BY177:BY178) -> 25722.466
B22: =Assumptions!B181 -> Professional Fees | F22: =SUM(Assumptions!R182:R184) -> 5500 | G22: =SUM(Assumptions!S182:S184) -> 5500 | H22: =SUM(Assumptions!T182:T184) -> 5500 | I22: =SUM(Assumptions!U182:U184) -> 5500 | J22: =SUM(Assumptions!V182:V184) -> 5500 | K22: =SUM(Assumptions!W182:W184) -> 5500 | L22: =SUM(Assumptions!X182:X184) -> 5500 | M22: =SUM(Assumptions!Y182:Y184) -> 5500 | ... BM22: =SUM(Assumptions!BY182:BY184) -> 5500
B23: =Assumptions!B187 -> Other | F23: =Assumptions!R188 -> 476.25 | G23: =Assumptions!S188 -> 963.39375 | H23: =Assumptions!T188 -> 1450.7009 | I23: =Assumptions!U188 -> 1938.0105 | J23: =Assumptions!V188 -> 2425.3202 | K23: =Assumptions!W188 -> 2912.6298 | L23: =Assumptions!X188 -> 3399.9394 | M23: =Assumptions!Y188 -> 3887.2491 | ... BM23: =Assumptions!BY188 -> 19653.082
B24: Total Operating Expenses | F24: =SUM(F19:F23) -> 238357.25 | G24: =SUM(G19:G23) -> 239234.11 | H24: =SUM(H19:H23) -> 240111.26 | I24: =SUM(I19:I23) -> 240988.42 | J24: =SUM(J19:J23) -> 241865.58 | K24: =SUM(K19:K23) -> 242742.73 | L24: =SUM(L19:L23) -> 243619.89 | M24: =SUM(M19:M23) -> 244497.05 | ... BM24: =SUM(BM19:BM23) -> 272875.55
B26: EBITDA | F26: =F15-F24 -> -235261.62 | G26: =G15-G24 -> -232972.05 | H26: =H15-H24 -> -230681.71 | I26: =I15-I24 -> -228391.35 | J26: =J15-J24 -> -226101 | K26: =K15-K24 -> -223810.64 | L26: =L15-L24 -> -221520.28 | M26: =M15-M24 -> -219229.93 | ... BM26: =BM15-BM24 -> -145130.51
B27: Depreciation | F27: =SUM(Assumptions!R209:R212)-sum(Assumptions!E209:E212) -> 0 | G27: =SUM(Assumptions!S209:S212)-sum(Assumptions!R209:R212) -> 0 | H27: =SUM(Assumptions!T209:T212)-sum(Assumptions!S209:S212) -> 0 | I27: =SUM(Assumptions!U209:U212)-sum(Assumptions!T209:T212) -> 0 | J27: =SUM(Assumptions!V209:V212)-sum(Assumptions!U209:U212) -> 0 | K27: =SUM(Assumptions!W209:W212)-sum(Assumptions!V209:V212) -> 0 | L27: =SUM(Assumptions!X209:X212)-sum(Assumptions!W209:W212) -> 0 | M27: =SUM(Assumptions!Y209:Y212)-sum(Assumptions!X209:X212) -> 0 | N27: =SUM(Assumptions!Z209:Z212)-sum(Assumptions!Y209:Y212) -> 0 | ... BM27: =SUM(Assumptions!BY209:BY212)-sum(Assumptions!BX209:BX212) -> 0
B28: EBIT | F28: =F26-F27 -> -235261.62 | G28: =G26-G27 -> -232972.05 | H28: =H26-H27 -> -230681.71 | I28: =I26-I27 -> -228391.35 | J28: =J26-J27 -> -226101 | K28: =K26-K27 -> -223810.64 | L28: =L26-L27 -> -221520.28 | M28: =M26-M27 -> -219229.93 | ... BM28: =BM26-BM27 -> -145130.51
B29: Taxes | F29: =IF(F28>0,F28*Assumptions!$C$190,0) -> 0 | G29: =IF(G28>0,G28*Assumptions!$C$190,0) -> 0 | H29: =IF(H28>0,H28*Assumptions!$C$190,0) -> 0 | I29: =IF(I28>0,I28*Assumptions!$C$190,0) -> 0 | J29: =IF(J28>0,J28*Assumptions!$C$190,0) -> 0 | K29: =IF(K28>0,K28*Assumptions!$C$190,0) -> 0 | L29: =IF(L28>0,L28*Assumptions!$C$190,0) -> 0 | M29: =IF(M28>0,M28*Assumptions!$C$190,0) -> 0 | ... BM29: =IF(BM28>0,BM28*Assumptions!$C$190,0) -> 0
B30: Net Income | F30: =F28-F29 -> -235261.62 | G30: =G28-G29 -> -232972.05 | H30: =H28-H29 -> -230681.71 | I30: =I28-I29 -> -228391.35 | J30: =J28-J29 -> -226101 | K30: =K28-K29 -> -223810.64 | L30: =L28-L29 -> -221520.28 | M30: =M28-M29 -> -219229.93 | ... BM30: =BM28-BM29 -> -145130.51
B31: Net Margin | F31: =F30/F8 -> -49.398766 | G31: =G30/G8 -> -24.182433 | H31: =H30/H8 -> -15.901397 | I31: =I30/I8 -> -11.784835 | J31: =J30/J8 -> -9.3225216 | K31: =K30/K8 -> -7.684143 | L31: =L30/L8 -> -6.5154185 | M31: =M30/M8 -> -5.6397191 | ... BM31: =BM30/BM8 -> -0.73846185
B33: Balance Sheet:
B35: Assets
B36: Current Assets
B37: Cash | F37: =F82 -> 333756.69 | G37: =G82 -> 148463.16 | H37: =H82 -> -39393.865 | I37: =I82 -> -229833.35 | J37: =J82 -> -422855.56 | K37: =K82 -> -618460.52 | L37: =L82 -> -816648.22 | M37: =M82 -> -1017418.7 | ... BM37: =BM82 -> -9397036.2
B38: Accounts Receivable | F38: =Assumptions!R200 -> 2381.25 | G38: =Assumptions!S200 -> 4816.9688 | H38: =Assumptions!T200 -> 7253.5045 | I38: =Assumptions!U200 -> 9690.0526 | J38: =Assumptions!V200 -> 12126.601 | K38: =Assumptions!W200 -> 14563.149 | L38: =Assumptions!X200 -> 16999.697 | M38: =Assumptions!Y200 -> 19436.245 | ... BM38: =Assumptions!BY200 -> 98265.411
B39: Total Current Assets | F39: =SUM(F37:F38) -> 336137.94 | G39: =SUM(G37:G38) -> 153280.13 | H39: =SUM(H37:H38) -> -32140.361 | I39: =SUM(I37:I38) -> -220143.29 | J39: =SUM(J37:J38) -> -410728.96 | K39: =SUM(K37:K38) -> -603897.37 | L39: =SUM(L37:L38) -> -799648.52 | M39: =SUM(M37:M38) -> -997982.42 | ... BM39: =SUM(BM37:BM38) -> -9298770.8
B41: Fixed Assets | F41: =SUM(Assumptions!R202:R206) -> 0 | G41: =SUM(Assumptions!S202:S206) -> 0 | H41: =SUM(Assumptions!T202:T206) -> 0 | I41: =SUM(Assumptions!U202:U206) -> 0 | J41: =SUM(Assumptions!V202:V206) -> 0 | K41: =SUM(Assumptions!W202:W206) -> 0 | L41: =SUM(Assumptions!X202:X206) -> 0 | M41: =SUM(Assumptions!Y202:Y206) -> 0 | ... BM41: =SUM(Assumptions!BY202:BY206) -> 0
B42: Accumulated Depreciation | F42: =-SUM(Assumptions!R209:R212) -> 0 | G42: =-SUM(Assumptions!S209:S212) -> 0 | H42: =-SUM(Assumptions!T209:T212) -> 0 | I42: =-SUM(Assumptions!U209:U212) -> 0 | J42: =-SUM(Assumptions!V209:V212) -> 0 | K42: =-SUM(Assumptions!W209:W212) -> 0 | L42: =-SUM(Assumptions!X209:X212) -> 0 | M42: =-SUM(Assumptions!Y209:Y212) -> 0 | ... BM42: =-SUM(Assumptions!BY209:BY212) -> 0
B43: Total Assets | F43: =SUM(F39:F42) -> 336137.94 | G43: =SUM(G39:G42) -> 153280.13 | H43: =SUM(H39:H42) -> -32140.361 | I43: =SUM(I39:I42) -> -220143.29 | J43: =SUM(J39:J42) -> -410728.96 | K43: =SUM(K39:K42) -> -603897.37 | L43: =SUM(L39:L42) -> -799648.52 | M43: =SUM(M39:M42) -> -997982.42 | ... BM43: =SUM(BM39:BM42) -> -9298770.8
B45: Liabilities & Owner's Equity
B46: Liabilities
B47: Accounts payable | F47: =Assumptions!R216 -> 19012.062 | G47: =Assumptions!S216 -> 20302.993 | H47: =Assumptions!T216 -> 21594.357 | I47: =Assumptions!U216 -> 22885.728 | J47: =Assumptions!V216 -> 24177.098 | K47: =Assumptions!W216 -> 25468.469 | L47: =Assumptions!X216 -> 26759.84 | M47: =Assumptions!Y216 -> 28051.21 | ... BM47: =Assumptions!BY216 -> 69830.668
B48: Deferred Revenue | F48: =Assumptions!R218 -> 52387.5 | G48: =Assumptions!S218 -> 101210.81 | H48: =Assumptions!T218 -> 145180.66 | I48: =Assumptions!U218 -> 184277.71 | J48: =Assumptions!V218 -> 218501.67 | K48: =Assumptions!W218 -> 247852.52 | L48: =Assumptions!X218 -> 272330.29 | M48: =Assumptions!Y218 -> 291934.95 | ... BN48: =Assumptions!BZ218
B49: Total Liabilities | F49: =SUM(F47:F48) -> 71399.562 | G49: =SUM(G47:G48) -> 121513.81 | H49: =SUM(H47:H48) -> 166775.02 | I49: =SUM(I47:I48) -> 207163.44 | J49: =SUM(J47:J48) -> 242678.76 | K49: =SUM(K47:K48) -> 273320.99 | L49: =SUM(L47:L48) -> 299090.13 | M49: =SUM(M47:M48) -> 319986.16 | ... BM49: =SUM(BM47:BM48) -> 1151002.4
B51: Equity | E51: Prev Cash
...
