Workbook

Sheet Overview
C2: YOUR LOGO HERE
C4: Financial Model
G5: Welcome! This template was created by Forecastr's team of Financial Analysts and Fractional CFOs to help our fellow founders create better financial models for their startups and small businesses. Forecastr is an out-of-the-box finance function for your business. We provide the tools and support you need to create an investor-grade financial model. Our analysts work with you every step of the way to build a model that's customized to fit your business, keep it up to date, and generate insightful reports to share with your investors and other stakeholders. ✔ Impress your investors ✔ Hit your growth targets ✔ Never run out of cash
C7: Your Website Link Here
C10: Table of Contents
C12: Assumptions
C14: Financials
I18: SCHEDULE A MODELING SESSION WITH A MEMBER OF OUR TEAM

Sheet Assumptions
B1: Year Counter | H1: 1 | I1: 1 | J1: 1 | K1: 1 | L1: 1 | M1: 1 | N1: 1 | O1: 1 | P1: 1 | Q1: 1 | R1: 1 | S1: 1 | T1: =H1+1 -> 2 | U1: =I1+1 -> 2 | V1: =J1+1 -> 2 | W1: =K1+1 -> 2 | X1: =L1+1 -> 2 | Y1: =M1+1 -> 2 | Z1: =N1+1 -> 2 | AA1: =O1+1 -> 2 | ... BO1: =BC1+1 -> 5
B2: Year | H2: =YEAR(H4) -> 2026 | I2: =YEAR(I4) -> 2026 | J2: =YEAR(J4) -> 2026 | K2: =YEAR(K4) -> 2026 | L2: =YEAR(L4) -> 2026 | M2: =YEAR(M4) -> 2026 | N2: =YEAR(N4) -> 2026 | O2: =YEAR(O4) -> 2026 | ... BO2: =YEAR(BO4) -> 2031
B3: Month Counter | H3: 1 | I3: =H3+1 -> 2 | J3: =I3+1 -> 3 | K3: =J3+1 -> 4 | L3: =K3+1 -> 5 | M3: =L3+1 -> 6 | N3: =M3+1 -> 7 | O3: =N3+1 -> 8 | P3: =O3+1 -> 9 | ... BO3: =BN3+1 -> 60
B4: Date | H4: =eomonth(today(),0) -> 46081 | I4: =EOMONTH(H4,1) -> 46112 | J4: =EOMONTH(I4,1) -> 46142 | K4: =EOMONTH(J4,1) -> 46173 | L4: =EOMONTH(K4,1) -> 46203 | M4: =EOMONTH(L4,1) -> 46234 | N4: =EOMONTH(M4,1) -> 46265 | O4: =EOMONTH(N4,1) -> 46295 | P4: =EOMONTH(O4,1) -> 46326 | ... BO4: =EOMONTH(BN4,1) -> 47879
B6: Customer Acquisition:
B8: Build Customer Acquisition Channels
B10: Organic / Word of Mouth
B11: Web Traffic | D11: 1000 | H11: =D11 -> 1000 | I11: =H11 -> 1000 | J11: =I11 -> 1000 | K11: =J11 -> 1000 | L11: =K11 -> 1000 | M11: =L11 -> 1000 | N11: =M11 -> 1000 | O11: =N11 -> 1000 | P11: =O11 -> 1000 | ... BO11: =BN11 -> 1000
B12: Conversion Rate | D12: 0.05 | H12: =D12 -> 0.05 | I12: =H12 -> 0.05 | J12: =I12 -> 0.05 | K12: =J12 -> 0.05 | L12: =K12 -> 0.05 | M12: =L12 -> 0.05 | N12: =M12 -> 0.05 | O12: =N12 -> 0.05 | P12: =O12 -> 0.05 | ... BO12: =BN12 -> 0.05
B13: New Customers | H13: =H11*H12 -> 50 | I13: =I11*I12 -> 50 | J13: =J11*J12 -> 50 | K13: =K11*K12 -> 50 | L13: =L11*L12 -> 50 | M13: =M11*M12 -> 50 | N13: =N11*N12 -> 50 | O13: =O11*O12 -> 50 | ... BO13: =BO11*BO12 -> 50
B15: Paid Advertising
B16: Budget per Month | D16: 5000 | H16: =D16 -> 5000 | I16: =H16 -> 5000 | J16: =I16 -> 5000 | K16: =J16 -> 5000 | L16: =K16 -> 5000 | M16: =L16 -> 5000 | N16: =M16 -> 5000 | O16: =N16 -> 5000 | P16: =O16 -> 5000 | ... BO16: =BN16 -> 5000
B17: Average CPC | D17: 2 | H17: =D17 -> 2 | I17: =H17 -> 2 | J17: =I17 -> 2 | K17: =J17 -> 2 | L17: =K17 -> 2 | M17: =L17 -> 2 | N17: =M17 -> 2 | O17: =N17 -> 2 | P17: =O17 -> 2 | ... BO17: =BN17 -> 2
B18: Conversion Rate | D18: 0.05 | H18: =D18 -> 0.05 | I18: =H18 -> 0.05 | J18: =I18 -> 0.05 | K18: =J18 -> 0.05 | L18: =K18 -> 0.05 | M18: =L18 -> 0.05 | N18: =M18 -> 0.05 | O18: =N18 -> 0.05 | P18: =O18 -> 0.05 | ... BO18: =BN18 -> 0.05
B19: New Customers | H19: =(H16/H17)*H18 -> 125 | I19: =(I16/I17)*I18 -> 125 | J19: =(J16/J17)*J18 -> 125 | K19: =(K16/K17)*K18 -> 125 | L19: =(L16/L17)*L18 -> 125 | M19: =(M16/M17)*M18 -> 125 | N19: =(N16/N17)*N18 -> 125 | O19: =(O16/O17)*O18 -> 125 | ... BO19: =(BO16/BO17)*BO18 -> 125
B21: Affiliates
B22: Number of Affiliates | D22: 5 | H22: =D22 -> 5 | I22: =H22 -> 5 | J22: =I22 -> 5 | K22: =J22 -> 5 | L22: =K22 -> 5 | M22: =L22 -> 5 | N22: =M22 -> 5 | O22: =N22 -> 5 | P22: =O22 -> 5 | ... BO22: =BN22 -> 5
B23: New Monthly Leads per Affiliate | D23: 50 | H23: =D23 -> 50 | I23: =H23 -> 50 | J23: =I23 -> 50 | K23: =J23 -> 50 | L23: =K23 -> 50 | M23: =L23 -> 50 | N23: =M23 -> 50 | O23: =N23 -> 50 | P23: =O23 -> 50 | ... BO23: =BN23 -> 50
B24: Conversion Rate | D24: 0.05 | H24: =D24 -> 0.05 | I24: =H24 -> 0.05 | J24: =I24 -> 0.05 | K24: =J24 -> 0.05 | L24: =K24 -> 0.05 | M24: =L24 -> 0.05 | N24: =M24 -> 0.05 | O24: =N24 -> 0.05 | P24: =O24 -> 0.05 | ... BO24: =BN24 -> 0.05
B25: New Customers | H25: =H22*H23*H24 -> 12.5 | I25: =I22*I23*I24 -> 12.5 | J25: =J22*J23*J24 -> 12.5 | K25: =K22*K23*K24 -> 12.5 | L25: =L22*L23*L24 -> 12.5 | M25: =M22*M23*M24 -> 12.5 | N25: =N22*N23*N24 -> 12.5 | O25: =O22*O23*O24 -> 12.5 | ... BO25: =BO22*BO23*BO24 -> 12.5
B27: Conferences
B28: Conferences Atteneded | H28: 1 | I28: 0 | J28: 0 | K28: 0 | L28: 0 | M28: 0 | N28: 0 | O28: 0 | P28: 0 | Q28: 0 | R28: 0 | S28: 0 | T28: 0 | U28: 0 | V28: 0 | W28: 0 | X28: 0 | Y28: 0 | Z28: 0 | AA28: 0 | AB28: 0 | AC28: 0 | AD28: 0 | AE28: 0 | AF28: 0 | AG28: 0 | AH28: 0 | AI28: 0 | AJ28: 0 | AK28: 0 | AL28: 0 | AM28: 0 | AN28: 0 | AO28: 0 | AP28: 0 | AQ28: 0 | AR28: 0 | AS28: 0 | AT28: 0 | AU28: 0 | AV28: 0 | AW28: 0 | AX28: 0 | AY28: 0 | AZ28: 0 | BA28: 0 | BB28: 0 | BC28: 0 | BD28: 0 | BE28: 0 | BF28: 0 | BG28: 0 | BH28: 0 | BI28: 0 | BJ28: 0 | BK28: 0 | BL28: 0 | BM28: 0 | BN28: 0 | BO28: 0
B29: New Leads per Conference | D29: 50 | H29: =D29 -> 50 | I29: =H29 -> 50 | J29: =I29 -> 50 | K29: =J29 -> 50 | L29: =K29 -> 50 | M29: =L29 -> 50 | N29: =M29 -> 50 | O29: =N29 -> 50 | P29: =O29 -> 50 | ... BO29: =BN29 -> 50
B30: Conversion Rate | D30: 0.05 | H30: =D30 -> 0.05 | I30: =H30 -> 0.05 | J30: =I30 -> 0.05 | K30: =J30 -> 0.05 | L30: =K30 -> 0.05 | M30: =L30 -> 0.05 | N30: =M30 -> 0.05 | O30: =N30 -> 0.05 | P30: =O30 -> 0.05 | ... BO30: =BN30 -> 0.05
B31: New Customers | H31: =H28*H29*H30 -> 2.5 | I31: =I28*I29*I30 -> 0 | J31: =J28*J29*J30 -> 0 | K31: =K28*K29*K30 -> 0 | L31: =L28*L29*L30 -> 0 | M31: =M28*M29*M30 -> 0 | N31: =N28*N29*N30 -> 0 | O31: =O28*O29*O30 -> 0 | ... BO31: =BO28*BO29*BO30 -> 0
B33: Influencers
B34: Number of Influencers | D34: 2 | H34: =D34 -> 2 | I34: =H34 -> 2 | J34: =I34 -> 2 | K34: =J34 -> 2 | L34: =K34 -> 2 | M34: =L34 -> 2 | N34: =M34 -> 2 | O34: =N34 -> 2 | P34: =O34 -> 2 | ... BO34: =BN34 -> 2
B35: New Monthly Posts per Influencer | D35: 100 | H35: =D35 -> 100 | I35: =H35 -> 100 | J35: =I35 -> 100 | K35: =J35 -> 100 | L35: =K35 -> 100 | M35: =L35 -> 100 | N35: =M35 -> 100 | O35: =N35 -> 100 | P35: =O35 -> 100 | ... BO35: =BN35 -> 100
B36: New Monthly Leads per Post | D36: 5 | H36: =D36 -> 5 | I36: =H36 -> 5 | J36: =I36 -> 5 | K36: =J36 -> 5 | L36: =K36 -> 5 | M36: =L36 -> 5 | N36: =M36 -> 5 | O36: =N36 -> 5 | P36: =O36 -> 5 | ... BO36: =BN36 -> 5
B37: Conversion Rate | D37: 0.05 | H37: =D37 -> 0.05 | I37: =H37 -> 0.05 | J37: =I37 -> 0.05 | K37: =J37 -> 0.05 | L37: =K37 -> 0.05 | M37: =L37 -> 0.05 | N37: =M37 -> 0.05 | O37: =N37 -> 0.05 | P37: =O37 -> 0.05 | ... BO37: =BN37 -> 0.05
B38: New Customers | H38: =H34*H35*H36*H37 -> 50 | I38: =I34*I35*I36*I37 -> 50 | J38: =J34*J35*J36*J37 -> 50 | K38: =K34*K35*K36*K37 -> 50 | L38: =L34*L35*L36*L37 -> 50 | M38: =M34*M35*M36*M37 -> 50 | N38: =N34*N35*N36*N37 -> 50 | O38: =O34*O35*O36*O37 -> 50 | ... BO38: =BO34*BO35*BO36*BO37 -> 50
B40: Customer Referrals
B41: Previous Months New Customers | D41: =C71 | H41: =G71 | I41: =H71 -> 267.5 | J41: =I71 -> 274.0125 | K41: =J71 -> 274.11019 | L41: =K71 -> 274.11165 | M41: =L71 -> 274.11167 | N41: =M71 -> 274.11168 | O41: =N71 -> 274.11168 | ... BO41: =BN71 -> 274.11168
B42: Referral Percentage | D42: 0.3 | H42: =D42 -> 0.3 | I42: =H42 -> 0.3 | J42: =I42 -> 0.3 | K42: =J42 -> 0.3 | L42: =K42 -> 0.3 | M42: =L42 -> 0.3 | N42: =M42 -> 0.3 | O42: =N42 -> 0.3 | P42: =O42 -> 0.3 | ... BO42: =BN42 -> 0.3
B43: Conversion Rate | D43: 0.05 | H43: =D43 -> 0.05 | I43: =H43 -> 0.05 | J43: =I43 -> 0.05 | K43: =J43 -> 0.05 | L43: =K43 -> 0.05 | M43: =L43 -> 0.05 | N43: =M43 -> 0.05 | O43: =N43 -> 0.05 | P43: =O43 -> 0.05 | ... BO43: =BN43 -> 0.05
B44: New Customers | H44: =H41*H42*H43 -> 0 | I44: =I41*I42*I43 -> 4.0125 | J44: =J41*J42*J43 -> 4.1101875 | K44: =K41*K42*K43 -> 4.1116528 | L44: =L41*L42*L43 -> 4.1116748 | M44: =M41*M42*M43 -> 4.1116751 | N44: =N41*N42*N43 -> 4.1116751 | O44: =O41*O42*O43 -> 4.1116751 | ... BO44: =BO41*BO42*BO43 -> 4.1116751
B46: Partnerships
B47: Active Partnerships | D47: 2 | H47: =D47 -> 2 | I47: =H47 -> 2 | J47: =I47 -> 2 | K47: =J47 -> 2 | L47: =K47 -> 2 | M47: =L47 -> 2 | N47: =M47 -> 2 | O47: =N47 -> 2 | P47: =O47 -> 2 | ... BO47: =BN47 -> 2
B48: New Monthly Leads per Partnership | D48: 100 | H48: =D48 -> 100 | I48: =H48 -> 100 | J48: =I48 -> 100 | K48: =J48 -> 100 | L48: =K48 -> 100 | M48: =L48 -> 100 | N48: =M48 -> 100 | O48: =N48 -> 100 | P48: =O48 -> 100 | ... BO48: =BN48 -> 100
B49: Conversion Rate | D49: 0.05 | H49: =D49 -> 0.05 | I49: =H49 -> 0.05 | J49: =I49 -> 0.05 | K49: =J49 -> 0.05 | L49: =K49 -> 0.05 | M49: =L49 -> 0.05 | N49: =M49 -> 0.05 | O49: =N49 -> 0.05 | P49: =O49 -> 0.05 | ... BO49: =BN49 -> 0.05
...

Sheet Financials
B1: Year Counter | F1: 1 | G1: 1 | H1: 1 | I1: 1 | J1: 1 | K1: 1 | L1: 1 | M1: 1 | N1: 1 | O1: 1 | P1: 1 | Q1: 1 | R1: =F1+1 -> 2 | S1: =G1+1 -> 2 | T1: =H1+1 -> 2 | U1: =I1+1 -> 2 | V1: =J1+1 -> 2 | W1: =K1+1 -> 2 | X1: =L1+1 -> 2 | Y1: =M1+1 -> 2 | ... BM1: =BA1+1 -> 5
B2: Year | F2: =YEAR(F4) -> 2026 | G2: =YEAR(G4) -> 2026 | H2: =YEAR(H4) -> 2026 | I2: =YEAR(I4) -> 2026 | J2: =YEAR(J4) -> 2026 | K2: =YEAR(K4) -> 2026 | L2: =YEAR(L4) -> 2026 | M2: =YEAR(M4) -> 2026 | ... BM2: =YEAR(BM4) -> 2031
B3: Month Counter | F3: 1 | G3: =F3+1 -> 2 | H3: =G3+1 -> 3 | I3: =H3+1 -> 4 | J3: =I3+1 -> 5 | K3: =J3+1 -> 6 | L3: =K3+1 -> 7 | M3: =L3+1 -> 8 | N3: =M3+1 -> 9 | ... BM3: =BL3+1 -> 60
B4: Date | F4: =Assumptions!H4 -> 46081 | G4: =EOMONTH(F4,1) -> 46112 | H4: =EOMONTH(G4,1) -> 46142 | I4: =EOMONTH(H4,1) -> 46173 | J4: =EOMONTH(I4,1) -> 46203 | K4: =EOMONTH(J4,1) -> 46234 | L4: =EOMONTH(K4,1) -> 46265 | M4: =EOMONTH(L4,1) -> 46295 | N4: =EOMONTH(M4,1) -> 46326 | ... BM4: =EOMONTH(BL4,1) -> 47879
B6: Income Statement:
B8: Revenue | F8: =sum(F9:F11) -> 12037.5 | G8: =sum(G9:G11) -> 24030.256 | H8: =sum(H9:H11) -> 35708.073 | I8: =sum(I9:I11) -> 47096.061 | J8: =sum(J9:J11) -> 58223.02 | K8: =sum(K9:K11) -> 69117.095 | L8: =sum(L9:L11) -> 79805.783 | M8: =sum(M9:M11) -> 90315.995 | ... BM8: =sum(BM9:BM11) -> 297176.97
B9: =Assumptions!B75 -> Per Unit Monthly SaaS Tier 1 | F9: =Assumptions!H86 -> 2675 | G9: =Assumptions!I86 -> 5545.4438 | H9: =Assumptions!J86 -> 8553.645 | I9: =Assumptions!K86 -> 11705.446 | J9: =Assumptions!L86 -> 15008.027 | K9: =Assumptions!M86 -> 18468.943 | L9: =Assumptions!N86 -> 22096.13 | M9: =Assumptions!O86 -> 25897.916 | ... BN9: =Assumptions!BP86
B10: =Assumptions!B88 -> Per Unit Monthly SaaS Tier 2 | F10: =Assumptions!H99 -> 4012.5 | G10: =Assumptions!I99 -> 7922.0625 | H10: =Assumptions!J99 -> 11637.612 | I10: =Assumptions!K99 -> 15167.406 | J10: =Assumptions!L99 -> 18520.711 | K10: =Assumptions!M99 -> 21706.351 | L10: =Assumptions!N99 -> 24732.708 | M10: =Assumptions!O99 -> 27607.748 | ... BN10: =Assumptions!BP99
B11: =Assumptions!B101 -> Per Unit Monthly SaaS Tier 3 | F11: =Assumptions!H112 -> 5350 | G11: =Assumptions!I112 -> 10562.75 | H11: =Assumptions!J112 -> 15516.816 | I11: =Assumptions!K112 -> 20223.208 | J11: =Assumptions!L112 -> 24694.282 | K11: =Assumptions!M112 -> 28941.801 | L11: =Assumptions!N112 -> 32976.944 | M11: =Assumptions!O112 -> 36810.331 | ... BN11: =Assumptions!BP112
B13: COGS | F13: =Assumptions!H157 -> 4213.125 | G13: =Assumptions!I157 -> 8410.5897 | H13: =Assumptions!J157 -> 12497.826 | I13: =Assumptions!K157 -> 16483.621 | J13: =Assumptions!L157 -> 20378.057 | K13: =Assumptions!M157 -> 24190.983 | L13: =Assumptions!N157 -> 27932.024 | M13: =Assumptions!O157 -> 31610.598 | ... BM13: =Assumptions!BO157 -> 104011.94
B15: Gross Profit | F15: =F8-F13 -> 7824.375 | G15: =G8-G13 -> 15619.667 | H15: =H8-H13 -> 23210.248 | I15: =I8-I13 -> 30612.439 | J15: =J8-J13 -> 37844.963 | K15: =K8-K13 -> 44926.112 | L15: =L8-L13 -> 51873.759 | M15: =M8-M13 -> 58705.397 | ... BM15: =BM8-BM13 -> 193165.03
B16: Gross Margin | F16: =F15/F8 -> 0.65 | G16: =G15/G8 -> 0.65 | H16: =H15/H8 -> 0.65 | I16: =I15/I8 -> 0.65 | J16: =J15/J8 -> 0.65 | K16: =K15/K8 -> 0.65 | L16: =L15/L8 -> 0.65 | M16: =M15/M8 -> 0.65 | ... BM16: =BM15/BM8 -> 0.65
B18: Operating Expenses
B19: Salaries & Benefits | F19: =SUM(Assumptions!H120:H144) -> 202000 | G19: =SUM(Assumptions!I120:I144) -> 202000 | H19: =SUM(Assumptions!J120:J144) -> 202000 | I19: =SUM(Assumptions!K120:K144) -> 202000 | J19: =SUM(Assumptions!L120:L144) -> 202000 | K19: =SUM(Assumptions!M120:M144) -> 202000 | L19: =SUM(Assumptions!N120:N144) -> 202000 | M19: =SUM(Assumptions!O120:O144) -> 202000 | ... BM19: =SUM(Assumptions!BO120:BO144) -> 202000
B20: =Assumptions!B159 -> General & Admin | F20: =sum(Assumptions!H160:H167) -> 20000 | G20: =sum(Assumptions!I160:I167) -> 20000 | H20: =sum(Assumptions!J160:J167) -> 20000 | I20: =sum(Assumptions!K160:K167) -> 20000 | J20: =sum(Assumptions!L160:L167) -> 20000 | K20: =sum(Assumptions!M160:M167) -> 20000 | L20: =sum(Assumptions!N160:N167) -> 20000 | M20: =sum(Assumptions!O160:O167) -> 20000 | ... BM20: =sum(Assumptions!BO160:BO167) -> 20000
B21: =Assumptions!B170 -> Sales & Marketing | F21: =sum(Assumptions!H171:H172) -> 10963 | G21: =sum(Assumptions!I171:I172) -> 11922.421 | H21: =sum(Assumptions!J171:J172) -> 12856.646 | I21: =sum(Assumptions!K171:K172) -> 13767.685 | J21: =sum(Assumptions!L171:L172) -> 14657.842 | K21: =sum(Assumptions!M171:M172) -> 15529.368 | L21: =sum(Assumptions!N171:N172) -> 16384.463 | M21: =sum(Assumptions!O171:O172) -> 17225.28 | ... BM21: =sum(Assumptions!BO171:BO172) -> 33774.157
B22: =Assumptions!B175 -> Professional Fees | F22: =SUM(Assumptions!H176:H178) -> 4000 | G22: =SUM(Assumptions!I176:I178) -> 4000 | H22: =SUM(Assumptions!J176:J178) -> 4000 | I22: =SUM(Assumptions!K176:K178) -> 4000 | J22: =SUM(Assumptions!L176:L178) -> 4000 | K22: =SUM(Assumptions!M176:M178) -> 4000 | L22: =SUM(Assumptions!N176:N178) -> 4000 | M22: =SUM(Assumptions!O176:O178) -> 4000 | ... BM22: =SUM(Assumptions!BO176:BO178) -> 4000
B23: =Assumptions!B181 -> Other | F23: =Assumptions!H182 -> 1203.75 | G23: =Assumptions!I182 -> 2403.0256 | H23: =Assumptions!J182 -> 3570.8073 | I23: =Assumptions!K182 -> 4709.6061 | J23: =Assumptions!L182 -> 5822.302 | K23: =Assumptions!M182 -> 6911.7095 | L23: =Assumptions!N182 -> 7980.5783 | M23: =Assumptions!O182 -> 9031.5995 | ... BM23: =Assumptions!BO182 -> 29717.697
B24: Total Operating Expenses | F24: =SUM(F19:F23) -> 238166.75 | G24: =SUM(G19:G23) -> 240325.45 | H24: =SUM(H19:H23) -> 242427.45 | I24: =SUM(I19:I23) -> 244477.29 | J24: =SUM(J19:J23) -> 246480.14 | K24: =SUM(K19:K23) -> 248441.08 | L24: =SUM(L19:L23) -> 250365.04 | M24: =SUM(M19:M23) -> 252256.88 | ... BM24: =SUM(BM19:BM23) -> 289491.85
B26: EBITDA | F26: =F15-F24 -> -230342.38 | G26: =G15-G24 -> -224705.78 | H26: =H15-H24 -> -219217.21 | I26: =I15-I24 -> -213864.85 | J26: =J15-J24 -> -208635.18 | K26: =K15-K24 -> -203514.97 | L26: =L15-L24 -> -198491.28 | M26: =M15-M24 -> -193551.48 | ... BM26: =BM15-BM24 -> -96326.826
B27: Depreciation | F27: =SUM(Assumptions!H203:H206)-sum(Assumptions!E203:E206) -> 0 | G27: =SUM(Assumptions!I203:I206)-sum(Assumptions!H203:H206) -> 0 | H27: =SUM(Assumptions!J203:J206)-sum(Assumptions!I203:I206) -> 0 | I27: =SUM(Assumptions!K203:K206)-sum(Assumptions!J203:J206) -> 0 | J27: =SUM(Assumptions!L203:L206)-sum(Assumptions!K203:K206) -> 0 | K27: =SUM(Assumptions!M203:M206)-sum(Assumptions!L203:L206) -> 0 | L27: =SUM(Assumptions!N203:N206)-sum(Assumptions!M203:M206) -> 0 | M27: =SUM(Assumptions!O203:O206)-sum(Assumptions!N203:N206) -> 0 | N27: =SUM(Assumptions!P203:P206)-sum(Assumptions!O203:O206) -> 0 | ... BM27: =SUM(Assumptions!BO203:BO206)-sum(Assumptions!BN203:BN206) -> 0
B28: EBIT | F28: =F26-F27 -> -230342.38 | G28: =G26-G27 -> -224705.78 | H28: =H26-H27 -> -219217.21 | I28: =I26-I27 -> -213864.85 | J28: =J26-J27 -> -208635.18 | K28: =K26-K27 -> -203514.97 | L28: =L26-L27 -> -198491.28 | M28: =M26-M27 -> -193551.48 | ... BM28: =BM26-BM27 -> -96326.826
B29: Taxes | F29: =IF(F28>0,F28*Assumptions!$C$184,0) -> 0 | G29: =IF(G28>0,G28*Assumptions!$C$184,0) -> 0 | H29: =IF(H28>0,H28*Assumptions!$C$184,0) -> 0 | I29: =IF(I28>0,I28*Assumptions!$C$184,0) -> 0 | J29: =IF(J28>0,J28*Assumptions!$C$184,0) -> 0 | K29: =IF(K28>0,K28*Assumptions!$C$184,0) -> 0 | L29: =IF(L28>0,L28*Assumptions!$C$184,0) -> 0 | M29: =IF(M28>0,M28*Assumptions!$C$184,0) -> 0 | ... BM29: =IF(BM28>0,BM28*Assumptions!$C$184,0) -> 0
B30: Net Income | F30: =F28-F29 -> -230342.38 | G30: =G28-G29 -> -224705.78 | H30: =H28-H29 -> -219217.21 | I30: =I28-I29 -> -213864.85 | J30: =J28-J29 -> -208635.18 | K30: =K28-K29 -> -203514.97 | L30: =L28-L29 -> -198491.28 | M30: =M28-M29 -> -193551.48 | ... BM30: =BM28-BM29 -> -96326.826
B31: Net Margin | F31: =F30/F8 -> -19.1354 | G31: =G30/G8 -> -9.3509523 | H31: =H30/H8 -> -6.1391496 | I31: =I30/I8 -> -4.5410348 | J31: =J30/J8 -> -3.5833796 | K31: =K30/K8 -> -2.9444953 | L31: =L30/L8 -> -2.4871792 | M31: =M30/M8 -> -2.1430477 | ... BM31: =BM30/BM8 -> -0.32413961
B33: Balance Sheet:
B35: Assets
B36: Current Assets
B37: Cash | F37: =F80 -> 283828.81 | G37: =G80 -> 56304.735 | H37: =H80 -> -165656.76 | I37: =I80 -> -382197.79 | J37: =J80 -> -593447.8 | K37: =K80 -> -799522.88 | L37: =L80 -> -1000526 | M37: =M80 -> -1196547.4 | ... BM37: =BM80 -> -7660701.2
B38: Accounts Receivable | F38: =Assumptions!H194 -> 6018.75 | G38: =Assumptions!I194 -> 12015.128 | H38: =Assumptions!J194 -> 17854.037 | I38: =Assumptions!K194 -> 23548.03 | J38: =Assumptions!L194 -> 29111.51 | K38: =Assumptions!M194 -> 34558.548 | L38: =Assumptions!N194 -> 39902.891 | M38: =Assumptions!O194 -> 45157.997 | ... BM38: =Assumptions!BO194 -> 148588.48
B39: Total Current Assets | F39: =SUM(F37:F38) -> 289847.56 | G39: =SUM(G37:G38) -> 68319.863 | H39: =SUM(H37:H38) -> -147802.72 | I39: =SUM(I37:I38) -> -358649.76 | J39: =SUM(J37:J38) -> -564336.29 | K39: =SUM(K37:K38) -> -764964.33 | L39: =SUM(L37:L38) -> -960623.11 | M39: =SUM(M37:M38) -> -1151389.4 | ... BM39: =SUM(BM37:BM38) -> -7512112.7
B41: Fixed Assets | F41: =SUM(Assumptions!H196:H200) -> 0 | G41: =SUM(Assumptions!I196:I200) -> 0 | H41: =SUM(Assumptions!J196:J200) -> 0 | I41: =SUM(Assumptions!K196:K200) -> 0 | J41: =SUM(Assumptions!L196:L200) -> 0 | K41: =SUM(Assumptions!M196:M200) -> 0 | L41: =SUM(Assumptions!N196:N200) -> 0 | M41: =SUM(Assumptions!O196:O200) -> 0 | ... BM41: =SUM(Assumptions!BO196:BO200) -> 0
B42: Accumulated Depreciation | F42: =-SUM(Assumptions!H203:H206) -> 0 | G42: =-SUM(Assumptions!I203:I206) -> 0 | H42: =-SUM(Assumptions!J203:J206) -> 0 | I42: =-SUM(Assumptions!K203:K206) -> 0 | J42: =-SUM(Assumptions!L203:L206) -> 0 | K42: =-SUM(Assumptions!M203:M206) -> 0 | L42: =-SUM(Assumptions!N203:N206) -> 0 | M42: =-SUM(Assumptions!O203:O206) -> 0 | ... BM42: =-SUM(Assumptions!BO203:BO206) -> 0
B43: Total Assets | F43: =SUM(F39:F42) -> 289847.56 | G43: =SUM(G39:G42) -> 68319.863 | H43: =SUM(H39:H42) -> -147802.72 | I43: =SUM(I39:I42) -> -358649.76 | J43: =SUM(J39:J42) -> -564336.29 | K43: =SUM(K39:K42) -> -764964.33 | L43: =SUM(L39:L42) -> -960623.11 | M43: =SUM(M39:M42) -> -1151389.4 | ... BM43: =SUM(BM39:BM42) -> -7512112.7
B45: Liabilities & Owner's Equity
B46: Liabilities
B47: Accounts payable | F47: =Assumptions!H210 -> 20189.938 | G47: =Assumptions!I210 -> 23368.018 | H47: =Assumptions!J210 -> 26462.639 | I47: =Assumptions!K210 -> 29480.456 | J47: =Assumptions!L210 -> 32429.1 | K47: =Assumptions!M210 -> 35316.03 | L47: =Assumptions!N210 -> 38148.532 | M47: =Assumptions!O210 -> 40933.739 | ... BM47: =Assumptions!BO210 -> 95751.896
B48: Total Liabilities | F48: =F47 -> 20189.938 | G48: =G47 -> 23368.018 | H48: =H47 -> 26462.639 | I48: =I47 -> 29480.456 | J48: =J47 -> 32429.1 | K48: =K47 -> 35316.03 | L48: =L47 -> 38148.532 | M48: =M47 -> 40933.739 | ... BM48: =BM47 -> 95751.896
B50: Equity | E50: Prev Cash
B51: Paid In Capital | E51: =Assumptions!C192 -> 500000 | F51: =E51 -> 500000 | G51: =Assumptions!I224+$E51 -> 500000 | H51: =Assumptions!J224+$E51 -> 500000 | I51: =Assumptions!K224+$E51 -> 500000 | J51: =Assumptions!L224+$E51 -> 500000 | K51: =Assumptions!M224+$E51 -> 500000 | L51: =Assumptions!N224+$E51 -> 500000 | M51: =Assumptions!O224+$E51 -> 500000 | N51: =Assumptions!P224+$E51 -> 500000 | ... BM51: =Assumptions!BO224+$E51 -> 500000
...
