Workbook

Sheet Overview
C2: YOUR LOGO HERE
C4: Financial Model
G5: Welcome! This template was created by Forecastr's team of Financial Analysts and Fractional CFOs to help our fellow founders create better financial models for their startups and small businesses. Forecastr is an out-of-the-box finance function for your business. We provide the tools and support you need to create an investor-grade financial model. Our analysts work with you every step of the way to build a model that's customized to fit your business, keep it up to date, and generate insightful reports to share with your investors and other stakeholders. ✔ Impress your investors ✔ Hit your growth targets ✔ Never run out of cash
C7: Your Website Link Here
C10: Table of Contents
C12: Assumptions
C14: Financials
I18: SCHEDULE A MODELING SESSION WITH A MEMBER OF OUR TEAM

Sheet Assumptions
B1: Year Counter | G1: 1 | H1: 1 | I1: 1 | J1: 1 | K1: 1 | L1: 1 | M1: 1 | N1: 1 | O1: 1 | P1: 1 | Q1: 1 | R1: 1 | S1: =G1+1 -> 2 | T1: =H1+1 -> 2 | U1: =I1+1 -> 2 | V1: =J1+1 -> 2 | W1: =K1+1 -> 2 | X1: =L1+1 -> 2 | Y1: =M1+1 -> 2 | Z1: =N1+1 -> 2 | ... BN1: =BB1+1 -> 5
B2: Year | G2: =YEAR(G4) -> 2026 | H2: =YEAR(H4) -> 2026 | I2: =YEAR(I4) -> 2026 | J2: =YEAR(J4) -> 2026 | K2: =YEAR(K4) -> 2026 | L2: =YEAR(L4) -> 2026 | M2: =YEAR(M4) -> 2026 | N2: =YEAR(N4) -> 2026 | ... BN2: =YEAR(BN4) -> 2031
B3: Month Counter | G3: 1 | H3: =G3+1 -> 2 | I3: =H3+1 -> 3 | J3: =I3+1 -> 4 | K3: =J3+1 -> 5 | L3: =K3+1 -> 6 | M3: =L3+1 -> 7 | N3: =M3+1 -> 8 | O3: =N3+1 -> 9 | ... BN3: =BM3+1 -> 60
B4: Date | G4: =eomonth(today(),0) -> 46081 | H4: =EOMONTH(G4,1) -> 46112 | I4: =EOMONTH(H4,1) -> 46142 | J4: =EOMONTH(I4,1) -> 46173 | K4: =EOMONTH(J4,1) -> 46203 | L4: =EOMONTH(K4,1) -> 46234 | M4: =EOMONTH(L4,1) -> 46265 | N4: =EOMONTH(M4,1) -> 46295 | O4: =EOMONTH(N4,1) -> 46326 | ... BN4: =EOMONTH(BM4,1) -> 47879
B6: Customer Acquisition:
B8: Build Customer Acquisition Channels
B10: Organic / Word of Mouth
B11: Web Traffic | D11: 1000 | G11: =D11 -> 1000 | H11: =G11 -> 1000 | I11: =H11 -> 1000 | J11: =I11 -> 1000 | K11: =J11 -> 1000 | L11: =K11 -> 1000 | M11: =L11 -> 1000 | N11: =M11 -> 1000 | O11: =N11 -> 1000 | ... BN11: =BM11 -> 1000
B12: Conversion Rate | D12: 0.05 | G12: =D12 -> 0.05 | H12: =G12 -> 0.05 | I12: =H12 -> 0.05 | J12: =I12 -> 0.05 | K12: =J12 -> 0.05 | L12: =K12 -> 0.05 | M12: =L12 -> 0.05 | N12: =M12 -> 0.05 | O12: =N12 -> 0.05 | ... BN12: =BM12 -> 0.05
B13: New Customers | G13: =G11*G12 -> 50 | H13: =H11*H12 -> 50 | I13: =I11*I12 -> 50 | J13: =J11*J12 -> 50 | K13: =K11*K12 -> 50 | L13: =L11*L12 -> 50 | M13: =M11*M12 -> 50 | N13: =N11*N12 -> 50 | ... BN13: =BN11*BN12 -> 50
B15: Paid Advertising
B16: Budget per Month | D16: 5000 | G16: =D16 -> 5000 | H16: =G16 -> 5000 | I16: =H16 -> 5000 | J16: =I16 -> 5000 | K16: =J16 -> 5000 | L16: =K16 -> 5000 | M16: =L16 -> 5000 | N16: =M16 -> 5000 | O16: =N16 -> 5000 | ... BN16: =BM16 -> 5000
B17: Average CPC | D17: 2 | G17: =D17 -> 2 | H17: =G17 -> 2 | I17: =H17 -> 2 | J17: =I17 -> 2 | K17: =J17 -> 2 | L17: =K17 -> 2 | M17: =L17 -> 2 | N17: =M17 -> 2 | O17: =N17 -> 2 | ... BN17: =BM17 -> 2
B18: Conversion Rate | D18: 0.05 | G18: =D18 -> 0.05 | H18: =G18 -> 0.05 | I18: =H18 -> 0.05 | J18: =I18 -> 0.05 | K18: =J18 -> 0.05 | L18: =K18 -> 0.05 | M18: =L18 -> 0.05 | N18: =M18 -> 0.05 | O18: =N18 -> 0.05 | ... BN18: =BM18 -> 0.05
B19: New Customers | G19: =(G16/G17)*G18 -> 125 | H19: =(H16/H17)*H18 -> 125 | I19: =(I16/I17)*I18 -> 125 | J19: =(J16/J17)*J18 -> 125 | K19: =(K16/K17)*K18 -> 125 | L19: =(L16/L17)*L18 -> 125 | M19: =(M16/M17)*M18 -> 125 | N19: =(N16/N17)*N18 -> 125 | ... BN19: =(BN16/BN17)*BN18 -> 125
B21: Affiliates
B22: Number of Affiliates | D22: 5 | G22: =D22 -> 5 | H22: =G22 -> 5 | I22: =H22 -> 5 | J22: =I22 -> 5 | K22: =J22 -> 5 | L22: =K22 -> 5 | M22: =L22 -> 5 | N22: =M22 -> 5 | O22: =N22 -> 5 | ... BN22: =BM22 -> 5
B23: New Monthly Leads per Affiliate | D23: 50 | G23: =D23 -> 50 | H23: =G23 -> 50 | I23: =H23 -> 50 | J23: =I23 -> 50 | K23: =J23 -> 50 | L23: =K23 -> 50 | M23: =L23 -> 50 | N23: =M23 -> 50 | O23: =N23 -> 50 | ... BN23: =BM23 -> 50
B24: Conversion Rate | D24: 0.05 | G24: =D24 -> 0.05 | H24: =G24 -> 0.05 | I24: =H24 -> 0.05 | J24: =I24 -> 0.05 | K24: =J24 -> 0.05 | L24: =K24 -> 0.05 | M24: =L24 -> 0.05 | N24: =M24 -> 0.05 | O24: =N24 -> 0.05 | ... BN24: =BM24 -> 0.05
B25: New Customers | G25: =G22*G23*G24 -> 12.5 | H25: =H22*H23*H24 -> 12.5 | I25: =I22*I23*I24 -> 12.5 | J25: =J22*J23*J24 -> 12.5 | K25: =K22*K23*K24 -> 12.5 | L25: =L22*L23*L24 -> 12.5 | M25: =M22*M23*M24 -> 12.5 | N25: =N22*N23*N24 -> 12.5 | ... BN25: =BN22*BN23*BN24 -> 12.5
B27: Conferences
B28: Conferences Atteneded | D28: 1 | G28: 1 | H28: 0 | I28: 0 | J28: 0 | K28: 1 | L28: 0 | M28: 0 | N28: 1 | O28: 0 | P28: 0 | Q28: 1 | R28: 0 | S28: 0 | T28: 0 | U28: 0 | V28: 0 | W28: 0 | X28: 0 | Y28: 0 | Z28: 0 | AA28: 0 | AB28: 0 | AC28: 0 | AD28: 0 | AE28: 0 | AF28: 0 | AG28: 0 | AH28: 0 | AI28: 0 | AJ28: 0 | AK28: 0 | AL28: 0 | AM28: 0 | AN28: 0 | AO28: 0 | AP28: 0 | AQ28: 0 | AR28: 0 | AS28: 0 | AT28: 0 | AU28: 0 | AV28: 0 | AW28: 0 | AX28: 0 | AY28: 0 | AZ28: 0 | BA28: 0 | BB28: 0 | BC28: 0 | BD28: 0 | BE28: 0 | BF28: 0 | BG28: 0 | BH28: 0 | BI28: 0 | BJ28: 0 | BK28: 0 | BL28: 0 | BM28: 0 | BN28: 0
B29: New Leads per Conference | D29: 50 | G29: =D29 -> 50 | H29: =G29 -> 50 | I29: =H29 -> 50 | J29: =I29 -> 50 | K29: =J29 -> 50 | L29: =K29 -> 50 | M29: =L29 -> 50 | N29: =M29 -> 50 | O29: =N29 -> 50 | ... BN29: =BM29 -> 50
B30: Conversion Rate | D30: 0.05 | G30: =D30 -> 0.05 | H30: =G30 -> 0.05 | I30: =H30 -> 0.05 | J30: =I30 -> 0.05 | K30: =J30 -> 0.05 | L30: =K30 -> 0.05 | M30: =L30 -> 0.05 | N30: =M30 -> 0.05 | O30: =N30 -> 0.05 | ... BN30: =BM30 -> 0.05
B31: New Customers | G31: =G28*G29*G30 -> 2.5 | H31: =H28*H29*H30 -> 0 | I31: =I28*I29*I30 -> 0 | J31: =J28*J29*J30 -> 0 | K31: =K28*K29*K30 -> 2.5 | L31: =L28*L29*L30 -> 0 | M31: =M28*M29*M30 -> 0 | N31: =N28*N29*N30 -> 2.5 | ... BN31: =BN28*BN29*BN30 -> 0
B33: Influencers
B34: Number of Influencers | D34: 2 | G34: =D34 -> 2 | H34: =G34 -> 2 | I34: =H34 -> 2 | J34: =I34 -> 2 | K34: =J34 -> 2 | L34: =K34 -> 2 | M34: =L34 -> 2 | N34: =M34 -> 2 | O34: =N34 -> 2 | ... BN34: =BM34 -> 2
B35: New Monthly Posts per Influencer | D35: 100 | G35: =D35 -> 100 | H35: =G35 -> 100 | I35: =H35 -> 100 | J35: =I35 -> 100 | K35: =J35 -> 100 | L35: =K35 -> 100 | M35: =L35 -> 100 | N35: =M35 -> 100 | O35: =N35 -> 100 | ... BN35: =BM35 -> 100
B36: New Monthly Leads per Post | D36: 5 | G36: =D36 -> 5 | H36: =G36 -> 5 | I36: =H36 -> 5 | J36: =I36 -> 5 | K36: =J36 -> 5 | L36: =K36 -> 5 | M36: =L36 -> 5 | N36: =M36 -> 5 | O36: =N36 -> 5 | ... BN36: =BM36 -> 5
B37: Conversion Rate | D37: 0.05 | G37: =D37 -> 0.05 | H37: =G37 -> 0.05 | I37: =H37 -> 0.05 | J37: =I37 -> 0.05 | K37: =J37 -> 0.05 | L37: =K37 -> 0.05 | M37: =L37 -> 0.05 | N37: =M37 -> 0.05 | O37: =N37 -> 0.05 | ... BN37: =BM37 -> 0.05
B38: New Customers | G38: =G34*G35*G36*G37 -> 50 | H38: =H34*H35*H36*H37 -> 50 | I38: =I34*I35*I36*I37 -> 50 | J38: =J34*J35*J36*J37 -> 50 | K38: =K34*K35*K36*K37 -> 50 | L38: =L34*L35*L36*L37 -> 50 | M38: =M34*M35*M36*M37 -> 50 | N38: =N34*N35*N36*N37 -> 50 | ... BN38: =BN34*BN35*BN36*BN37 -> 50
B40: Customer Referrals
B41: Previous Months New Customers | D41: =C71 | G41: =F71 | H41: =G71 -> 267.5 | I41: =H71 -> 269.0125 | J41: =I71 -> 274.03519 | K41: =J71 -> 274.11053 | L41: =K71 -> 276.61166 | M41: =L71 -> 274.14917 | N41: =M71 -> 274.11224 | ... BN41: =BM71 -> 274.11168
B42: Referral Percentage | D42: 0.3 | G42: =D42 -> 0.3 | H42: =G42 -> 0.3 | I42: =H42 -> 0.3 | J42: =I42 -> 0.3 | K42: =J42 -> 0.3 | L42: =K42 -> 0.3 | M42: =L42 -> 0.3 | N42: =M42 -> 0.3 | O42: =N42 -> 0.3 | ... BN42: =BM42 -> 0.3
B43: Conversion Rate | D43: 0.05 | G43: =D43 -> 0.05 | H43: =G43 -> 0.05 | I43: =H43 -> 0.05 | J43: =I43 -> 0.05 | K43: =J43 -> 0.05 | L43: =K43 -> 0.05 | M43: =L43 -> 0.05 | N43: =M43 -> 0.05 | O43: =N43 -> 0.05 | ... BN43: =BM43 -> 0.05
B44: New Customers | G44: =G41*G42*G43 -> 0 | H44: =H41*H42*H43 -> 4.0125 | I44: =I41*I42*I43 -> 4.0351875 | J44: =J41*J42*J43 -> 4.1105278 | K44: =K41*K42*K43 -> 4.1116579 | L44: =L41*L42*L43 -> 4.1491749 | M44: =M41*M42*M43 -> 4.1122376 | N44: =N41*N42*N43 -> 4.1116836 | ... BN44: =BN41*BN42*BN43 -> 4.1116751
B46: Partnerships
B47: Active Partnerships | D47: 2 | G47: =D47 -> 2 | H47: =G47 -> 2 | I47: =H47 -> 2 | J47: =I47 -> 2 | K47: =J47 -> 2 | L47: =K47 -> 2 | M47: =L47 -> 2 | N47: =M47 -> 2 | O47: =N47 -> 2 | ... BN47: =BM47 -> 2
B48: New Monthly Leads per Partnership | D48: 100 | G48: =D48 -> 100 | H48: =G48 -> 100 | I48: =H48 -> 100 | J48: =I48 -> 100 | K48: =J48 -> 100 | L48: =K48 -> 100 | M48: =L48 -> 100 | N48: =M48 -> 100 | O48: =N48 -> 100 | ... BN48: =BM48 -> 100
B49: Conversion Rate | D49: 0.05 | G49: =D49 -> 0.05 | H49: =G49 -> 0.05 | I49: =H49 -> 0.05 | J49: =I49 -> 0.05 | K49: =J49 -> 0.05 | L49: =K49 -> 0.05 | M49: =L49 -> 0.05 | N49: =M49 -> 0.05 | O49: =N49 -> 0.05 | ... BN49: =BM49 -> 0.05
...

Sheet Financials
B1: Year Counter | F1: 1 | G1: 1 | H1: 1 | I1: 1 | J1: 1 | K1: 1 | L1: 1 | M1: 1 | N1: 1 | O1: 1 | P1: 1 | Q1: 1 | R1: =F1+1 -> 2 | S1: =G1+1 -> 2 | T1: =H1+1 -> 2 | U1: =I1+1 -> 2 | V1: =J1+1 -> 2 | W1: =K1+1 -> 2 | X1: =L1+1 -> 2 | Y1: =M1+1 -> 2 | ... BM1: =BA1+1 -> 5
B2: Year | F2: =YEAR(F4) -> 2026 | G2: =YEAR(G4) -> 2026 | H2: =YEAR(H4) -> 2026 | I2: =YEAR(I4) -> 2026 | J2: =YEAR(J4) -> 2026 | K2: =YEAR(K4) -> 2026 | L2: =YEAR(L4) -> 2026 | M2: =YEAR(M4) -> 2026 | ... BM2: =YEAR(BM4) -> 2031
B3: Month Counter | F3: 1 | G3: =F3+1 -> 2 | H3: =G3+1 -> 3 | I3: =H3+1 -> 4 | J3: =I3+1 -> 5 | K3: =J3+1 -> 6 | L3: =K3+1 -> 7 | M3: =L3+1 -> 8 | N3: =M3+1 -> 9 | ... BM3: =BL3+1 -> 60
B4: Date | F4: =Assumptions!G4 -> 46081 | G4: =EOMONTH(F4,1) -> 46112 | H4: =EOMONTH(G4,1) -> 46142 | I4: =EOMONTH(H4,1) -> 46173 | J4: =EOMONTH(I4,1) -> 46203 | K4: =EOMONTH(J4,1) -> 46234 | L4: =EOMONTH(K4,1) -> 46265 | M4: =EOMONTH(L4,1) -> 46295 | N4: =EOMONTH(M4,1) -> 46326 | ... BM4: =EOMONTH(BL4,1) -> 47879
B6: Income Statement:
B8: Revenue | F8: =Assumptions!G86 -> 13375 | G8: =Assumptions!H86 -> 20138.125 | H8: =Assumptions!I86 -> 23770.822 | I8: =Assumptions!J86 -> 25590.937 | J8: =Assumptions!K86 -> 26626.052 | K8: =Assumptions!L86 -> 27020.485 | L8: =Assumptions!M86 -> 27215.854 | M8: =Assumptions!N86 -> 27438.511 | ... BM8: =Assumptions!BN86 -> 27411.168
B10: COGS | F10: =Assumptions!G130 -> 4681.25 | G10: =Assumptions!H130 -> 7048.3438 | H10: =Assumptions!I130 -> 8319.7877 | I10: =Assumptions!J130 -> 8956.8281 | J10: =Assumptions!K130 -> 9319.118 | K10: =Assumptions!L130 -> 9457.1696 | L10: =Assumptions!M130 -> 9525.549 | M10: =Assumptions!N130 -> 9603.4789 | ... BM10: =Assumptions!BN130 -> 9593.9086
B12: Gross Profit | F12: =F8-F10 -> 8693.75 | G12: =G8-G10 -> 13089.781 | H12: =H8-H10 -> 15451.034 | I12: =I8-I10 -> 16634.109 | J12: =J8-J10 -> 17306.934 | K12: =K8-K10 -> 17563.315 | L12: =L8-L10 -> 17690.305 | M12: =M8-M10 -> 17835.032 | ... BM12: =BM8-BM10 -> 17817.259
B13: Gross Margin | F13: =F12/F8 -> 0.65 | G13: =G12/G8 -> 0.65 | H13: =H12/H8 -> 0.65 | I13: =I12/I8 -> 0.65 | J13: =J12/J8 -> 0.65 | K13: =K12/K8 -> 0.65 | L13: =L12/L8 -> 0.65 | M13: =M12/M8 -> 0.65 | ... BM13: =BM12/BM8 -> 0.65
B15: Operating Expenses
B16: Salaries & Benefits | F16: =SUM(Assumptions!G93:G117) -> 202000 | G16: =SUM(Assumptions!H93:H117) -> 202000 | H16: =SUM(Assumptions!I93:I117) -> 202000 | I16: =SUM(Assumptions!J93:J117) -> 202000 | J16: =SUM(Assumptions!K93:K117) -> 202000 | K16: =SUM(Assumptions!L93:L117) -> 202000 | L16: =SUM(Assumptions!M93:M117) -> 202000 | M16: =SUM(Assumptions!N93:N117) -> 202000 | ... BM16: =SUM(Assumptions!BN93:BN117) -> 202000
B17: =Assumptions!B132 -> General & Admin | F17: =sum(Assumptions!G133:G140) -> 20000 | G17: =sum(Assumptions!H133:H140) -> 20000 | H17: =sum(Assumptions!I133:I140) -> 20000 | I17: =sum(Assumptions!J133:J140) -> 20000 | J17: =sum(Assumptions!K133:K140) -> 20000 | K17: =sum(Assumptions!L133:L140) -> 20000 | L17: =sum(Assumptions!M133:M140) -> 20000 | M17: =sum(Assumptions!N133:N140) -> 20000 | ... BM17: =sum(Assumptions!BN133:BN140) -> 20000
B18: =Assumptions!B143 -> Sales & Marketing | F18: =sum(Assumptions!G144:G145) -> 11070 | G18: =sum(Assumptions!H144:H145) -> 11611.05 | H18: =sum(Assumptions!I144:I145) -> 11901.666 | I18: =sum(Assumptions!J144:J145) -> 12047.275 | J18: =sum(Assumptions!K144:K145) -> 12130.084 | K18: =sum(Assumptions!L144:L145) -> 12161.639 | L18: =sum(Assumptions!M144:M145) -> 12177.268 | M18: =sum(Assumptions!N144:N145) -> 12195.081 | ... BM18: =sum(Assumptions!BN144:BN145) -> 12192.893
B19: =Assumptions!B148 -> Professional Fees | F19: =SUM(Assumptions!G149:G151) -> 5000 | G19: =SUM(Assumptions!H149:H151) -> 5000 | H19: =SUM(Assumptions!I149:I151) -> 5000 | I19: =SUM(Assumptions!J149:J151) -> 5000 | J19: =SUM(Assumptions!K149:K151) -> 5000 | K19: =SUM(Assumptions!L149:L151) -> 5000 | L19: =SUM(Assumptions!M149:M151) -> 5000 | M19: =SUM(Assumptions!N149:N151) -> 5000 | ... BM19: =SUM(Assumptions!BN149:BN151) -> 5000
B20: =Assumptions!B154 -> Other | F20: =Assumptions!G155 -> 1337.5 | G20: =Assumptions!H155 -> 2013.8125 | H20: =Assumptions!I155 -> 2377.0822 | I20: =Assumptions!J155 -> 2559.0937 | J20: =Assumptions!K155 -> 2662.6052 | K20: =Assumptions!L155 -> 2702.0485 | L20: =Assumptions!M155 -> 2721.5854 | M20: =Assumptions!N155 -> 2743.8511 | ... BM20: =Assumptions!BN155 -> 2741.1168
B21: Total Operating Expenses | F21: =SUM(F16:F20) -> 239407.5 | G21: =SUM(G16:G20) -> 240624.86 | H21: =SUM(H16:H20) -> 241278.75 | I21: =SUM(I16:I20) -> 241606.37 | J21: =SUM(J16:J20) -> 241792.69 | K21: =SUM(K16:K20) -> 241863.69 | L21: =SUM(L16:L20) -> 241898.85 | M21: =SUM(M16:M20) -> 241938.93 | ... BM21: =SUM(BM16:BM20) -> 241934.01
B23: EBITDA | F23: =F12-F21 -> -230713.75 | G23: =G12-G21 -> -227535.08 | H23: =H12-H21 -> -225827.71 | I23: =I12-I21 -> -224972.26 | J23: =J12-J21 -> -224485.76 | K23: =K12-K21 -> -224300.37 | L23: =L12-L21 -> -224208.55 | M23: =M12-M21 -> -224103.9 | ... BM23: =BM12-BM21 -> -224116.75
B24: Depreciation | F24: =SUM(Assumptions!G176:G179)-sum(Assumptions!E176:E179) -> 0 | G24: =SUM(Assumptions!H176:H179)-sum(Assumptions!G176:G179) -> 0 | H24: =SUM(Assumptions!I176:I179)-sum(Assumptions!H176:H179) -> 0 | I24: =SUM(Assumptions!J176:J179)-sum(Assumptions!I176:I179) -> 0 | J24: =SUM(Assumptions!K176:K179)-sum(Assumptions!J176:J179) -> 0 | K24: =SUM(Assumptions!L176:L179)-sum(Assumptions!K176:K179) -> 0 | L24: =SUM(Assumptions!M176:M179)-sum(Assumptions!L176:L179) -> 0 | M24: =SUM(Assumptions!N176:N179)-sum(Assumptions!M176:M179) -> 0 | N24: =SUM(Assumptions!O176:O179)-sum(Assumptions!N176:N179) -> 0 | ... BM24: =SUM(Assumptions!BN176:BN179)-sum(Assumptions!BM176:BM179) -> 0
B25: EBIT | F25: =F23-F24 -> -230713.75 | G25: =G23-G24 -> -227535.08 | H25: =H23-H24 -> -225827.71 | I25: =I23-I24 -> -224972.26 | J25: =J23-J24 -> -224485.76 | K25: =K23-K24 -> -224300.37 | L25: =L23-L24 -> -224208.55 | M25: =M23-M24 -> -224103.9 | ... BM25: =BM23-BM24 -> -224116.75
B26: Taxes | F26: =IF(F25>0,F25*Assumptions!$C$157,0) -> 0 | G26: =IF(G25>0,G25*Assumptions!$C$157,0) -> 0 | H26: =IF(H25>0,H25*Assumptions!$C$157,0) -> 0 | I26: =IF(I25>0,I25*Assumptions!$C$157,0) -> 0 | J26: =IF(J25>0,J25*Assumptions!$C$157,0) -> 0 | K26: =IF(K25>0,K25*Assumptions!$C$157,0) -> 0 | L26: =IF(L25>0,L25*Assumptions!$C$157,0) -> 0 | M26: =IF(M25>0,M25*Assumptions!$C$157,0) -> 0 | ... BM26: =IF(BM25>0,BM25*Assumptions!$C$157,0) -> 0
B27: Net Income | F27: =F25-F26 -> -230713.75 | G27: =G25-G26 -> -227535.08 | H27: =H25-H26 -> -225827.71 | I27: =I25-I26 -> -224972.26 | J27: =J25-J26 -> -224485.76 | K27: =K25-K26 -> -224300.37 | L27: =L25-L26 -> -224208.55 | M27: =M25-M26 -> -224103.9 | ... BM27: =BM25-BM26 -> -224116.75
B28: Net Margin | F28: =F27/F8 -> -17.249626 | G28: =G27/G8 -> -11.298722 | H28: =H27/H8 -> -9.5002064 | I28: =I27/I8 -> -8.791091 | J28: =J27/J8 -> -8.4310569 | K28: =K27/K8 -> -8.3011232 | L28: =L27/L8 -> -8.2381595 | M28: =M27/M8 -> -8.1674949 | ... BM28: =BM27/BM8 -> -8.1761111
B30: Balance Sheet:
B32: Assets
B33: Current Assets
B34: Cash | F34: =F77 -> 283643.12 | G34: =G77 -> 54518.709 | H34: =H77 -> -172162.69 | I34: =I77 -> -397562.67 | J34: =J77 -> -622291.68 | K34: =K77 -> -846684.75 | L34: =L77 -> -1070939.2 | M34: =M77 -> -1295095.4 | ... BM34: =BM77 -> -12949026
B35: Accounts Receivable | F35: =Assumptions!G167 -> 6687.5 | G35: =Assumptions!H167 -> 10069.062 | H35: =Assumptions!I167 -> 11885.411 | I35: =Assumptions!J167 -> 12795.469 | J35: =Assumptions!K167 -> 13313.026 | K35: =Assumptions!L167 -> 13510.242 | L35: =Assumptions!M167 -> 13607.927 | M35: =Assumptions!N167 -> 13719.256 | ... BM35: =Assumptions!BN167 -> 13705.584
B36: Total Current Assets | F36: =SUM(F34:F35) -> 290330.62 | G36: =SUM(G34:G35) -> 64587.772 | H36: =SUM(H34:H35) -> -160277.28 | I36: =SUM(I34:I35) -> -384767.21 | J36: =SUM(J34:J35) -> -608978.66 | K36: =SUM(K34:K35) -> -833174.5 | L36: =SUM(L34:L35) -> -1057331.3 | M36: =SUM(M34:M35) -> -1281376.2 | ... BM36: =SUM(BM34:BM35) -> -12935321
B38: Fixed Assets | F38: =SUM(Assumptions!G169:G173) -> 0 | G38: =SUM(Assumptions!H169:H173) -> 0 | H38: =SUM(Assumptions!I169:I173) -> 0 | I38: =SUM(Assumptions!J169:J173) -> 0 | J38: =SUM(Assumptions!K169:K173) -> 0 | K38: =SUM(Assumptions!L169:L173) -> 0 | L38: =SUM(Assumptions!M169:M173) -> 0 | M38: =SUM(Assumptions!N169:N173) -> 0 | ... BM38: =SUM(Assumptions!BN169:BN173) -> 0
B39: Accumulated Depreciation | F39: =-SUM(Assumptions!G176:G179) -> 0 | G39: =-SUM(Assumptions!H176:H179) -> 0 | H39: =-SUM(Assumptions!I176:I179) -> 0 | I39: =-SUM(Assumptions!J176:J179) -> 0 | J39: =-SUM(Assumptions!K176:K179) -> 0 | K39: =-SUM(Assumptions!L176:L179) -> 0 | L39: =-SUM(Assumptions!M176:M179) -> 0 | M39: =-SUM(Assumptions!N176:N179) -> 0 | ... BM39: =-SUM(Assumptions!BN176:BN179) -> 0
B40: Total Assets | F40: =SUM(F36:F39) -> 290330.62 | G40: =SUM(G36:G39) -> 64587.772 | H40: =SUM(H36:H39) -> -160277.28 | I40: =SUM(I36:I39) -> -384767.21 | J40: =SUM(J36:J39) -> -608978.66 | K40: =SUM(K36:K39) -> -833174.5 | L40: =SUM(L36:L39) -> -1057331.3 | M40: =SUM(M36:M39) -> -1281376.2 | ... BM40: =SUM(BM36:BM39) -> -12935321
B42: Liabilities & Owner's Equity
B43: Liabilities
B44: Accounts payable | F44: =Assumptions!G183 -> 21044.375 | G44: =Assumptions!H183 -> 22836.603 | H44: =Assumptions!I183 -> 23799.268 | I44: =Assumptions!J183 -> 24281.598 | J44: =Assumptions!K183 -> 24555.904 | K44: =Assumptions!L183 -> 24660.428 | L44: =Assumptions!M183 -> 24712.201 | M44: =Assumptions!N183 -> 24771.205 | ... BM44: =Assumptions!BN183 -> 24763.959
B45: Total Liabilities | F45: =F44 -> 21044.375 | G45: =G44 -> 22836.603 | H45: =H44 -> 23799.268 | I45: =I44 -> 24281.598 | J45: =J44 -> 24555.904 | K45: =K44 -> 24660.428 | L45: =L44 -> 24712.201 | M45: =M44 -> 24771.205 | ... BM45: =BM44 -> 24763.959
B47: Equity | E47: Prev Cash
B48: Paid In Capital | E48: =Assumptions!C165 -> 500000 | F48: =E48 -> 500000 | G48: =Assumptions!H197+$E48 -> 500000 | H48: =Assumptions!I197+$E48 -> 500000 | I48: =Assumptions!J197+$E48 -> 500000 | J48: =Assumptions!K197+$E48 -> 500000 | K48: =Assumptions!L197+$E48 -> 500000 | L48: =Assumptions!M197+$E48 -> 500000 | M48: =Assumptions!N197+$E48 -> 500000 | N48: =Assumptions!O197+$E48 -> 500000 | ... BM48: =Assumptions!BN197+$E48 -> 500000
B49: Accumulated Retained Earnings | F49: =E49+F27 -> -230713.75 | G49: =F49+G27 -> -458248.83 | H49: =G49+H27 -> -684076.55 | I49: =H49+I27 -> -909048.8 | J49: =I49+J27 -> -1133534.6 | K49: =J49+K27 -> -1357834.9 | L49: =K49+L27 -> -1582043.5 | M49: =L49+M27 -> -1806147.4 | ... BM49: =BL49+BM27 -> -13460085
B50: Total Equity | F50: =SUM(F48:F49) -> 269286.25 | G50: =SUM(G48:G49) -> 41751.169 | H50: =SUM(H48:H49) -> -184076.55 | I50: =SUM(I48:I49) -> -409048.8 | J50: =SUM(J48:J49) -> -633534.56 | K50: =SUM(K48:K49) -> -857834.93 | L50: =SUM(L48:L49) -> -1082043.5 | M50: =SUM(M48:M49) -> -1306147.4 | ... BM50: =SUM(BM48:BM49) -> -12960085
B52: Total Liabilities & Owner's Equity | F52: =F50+F45 -> 290330.62 | G52: =G50+G45 -> 64587.772 | H52: =H50+H45 -> -160277.28 | I52: =I50+I45 -> -384767.21 | J52: =J50+J45 -> -608978.66 | K52: =K50+K45 -> -833174.5 | L52: =L50+L45 -> -1057331.3 | M52: =M50+M45 -> -1281376.2 | ... BM52: =BM50+BM45 -> -12935321
...
